Workbook

Sheet Анализ
G2: Средний вход | H2: =AVERAGE(G7:G1005) -> #N/A | I2: Средний срок, д | J2: =AVERAGE(M7:M1005) -> #N/A | K2: Ср.комиссия | L2: =AVERAGE(D7:D1005) -> #N/A
A3: Кошелек | B3: Последняя транзакция | C3: Тройная транзакция | D3: Последние "х" дней | E3: Win Rate R | F3: =COUNTIFS(F7:F1005,0,I7:I1005,">"&0)/COUNTIF(F7:F1005,0) -> #DIV/0! | G3: P&L R | H3: =SUMIF(F7:F1005,0,I7:I1005) -> 0 | I3: Avarage R | J3: =AVERAGEIF(F7:F1005,0,J7:J1005) -> #DIV/0! | K3: Сделок | L3: =COUNTA(A7:A1005) -> 1
B4: =MAX('Барабан'!AJ:AJ) -> 0 | C4: {=SUM(IF('Барабан'!AJ2:AJ1000>TODAY()-30,IF(LEN('Барабан'!W2:W1000)>90,1,0),0))} -> 0 | D4: 120 | E4: Win Rate Total | F4: =COUNTIF(I7:I1005,">"&0)/L3 -> 0 | G4: P&L Total | H4: =SUM(I7:I1005) -> #N/A | I4: Avarage Total | J4: =AVERAGE(J7:J1005) -> #DIV/0! | K4: Комиссий | L4: =SUM(D7:D1005) -> #N/A
A6: Тикеры | B6: Всего купили | C6: Всего продали | D6: Комиссия, usd | E6: Дельта | F6: Накопление, usd | G6: Сумма покупок, usd | H6: Сумма продаж, usd | I6: Дельта, usd | J6: Дельта, % usd | K6: Покупок | L6: Продаж | M6: Срок сделки, д | N6: Первая покупка | O6: Последняя продажа
A7: ='Справочник'!E2 -> #N/A | B7: =IF(A7>0,SUMIF('Барабан'!K:K,A7,'Барабан'!I:I),"") -> #N/A | C7: =IF(A7>0,SUMIF('Барабан'!V:V,A7,'Барабан'!T:T),"") -> #N/A | D7: =IF(A7>0,SUMIF('Барабан'!K:K,A7,'Барабан'!AG:AG)+SUMIF('Барабан'!V:V,A7,'Барабан'!AG:AG),"") -> #N/A | E7: =IF(A7>0,ROUND(B7-C7,0),"") -> #N/A | F7: {=IFERROR(IF(E7=0,0,INDEX('Справочник'!G:G,MATCH(A7,'Справочник'!F:F,0))))} | G7: =IF(A7>0,SUMIF('Барабан'!K:K,A7,'Барабан'!P:P),"") -> #N/A | H7: =IF(A7>0,SUMIF('Барабан'!V:V,A7,'Барабан'!AA:AA),"") -> #N/A | I7: =IF(A7>0,H7+F7-G7,"") -> #N/A | J7: =IFERROR(IF(A7>0,I7/G7,""),"–") -> – | K7: =IF(A7>0,COUNTIF('Барабан'!K:K,A7),"") -> #N/A | L7: =IF(A7>0,COUNTIF('Барабан'!V:V,A7),"") -> #N/A | M7: =IF(A7>0,IFERROR(O7-N7,TODAY()-N7),"") -> #N/A | N7: =IFERROR(__xludf.DUMMYFUNCTION("IF(A7>0,MIN(FILTER('Барабан'!AJ:AJ,'Барабан'!K:K=A7)),"""")"),"#N/A") -> #N/A | O7: =IFERROR(__xludf.DUMMYFUNCTION("IF(A7>0,IFERROR(MAX(FILTER('Барабан'!AJ:AJ,'Барабан'!V:V=A7)),""–""),"""")"),"#N/A") -> #N/A
A8: ='Справочник'!E3 | B8: =IF(A8>0,SUMIF('Барабан'!K:K,A8,'Барабан'!I:I),"") | C8: =IF(A8>0,SUMIF('Барабан'!V:V,A8,'Барабан'!T:T),"") | D8: =IF(A8>0,SUMIF('Барабан'!K:K,A8,'Барабан'!AG:AG)+SUMIF('Барабан'!V:V,A8,'Барабан'!AG:AG),"") | E8: =IF(A8>0,ROUND(B8-C8,0),"") | F8: {=IFERROR(IF(E8=0,0,INDEX('Справочник'!G:G,MATCH(A8,'Справочник'!F:F,0))))} | G8: =IF(A8>0,SUMIF('Барабан'!K:K,A8,'Барабан'!P:P),"") | H8: =IF(A8>0,SUMIF('Барабан'!V:V,A8,'Барабан'!AA:AA),"") | I8: =IF(A8>0,H8+F8-G8-D8,"") | J8: =IFERROR(IF(A8>0,I8/G8,""),"–") | K8: =IF(A8>0,COUNTIF('Барабан'!K:K,A8),"") | L8: =IF(A8>0,COUNTIF('Барабан'!V:V,A8),"") | M8: =IF(A8>0,IFERROR(O8-N8,TODAY()-N8),"") | N8: =IFERROR(__xludf.DUMMYFUNCTION("IF(A8>0,MIN(FILTER('Барабан'!AJ:AJ,'Барабан'!K:K=A8)),"""")"),"") | O8: =IFERROR(__xludf.DUMMYFUNCTION("IF(A8>0,IFERROR(MAX(FILTER('Барабан'!AJ:AJ,'Барабан'!V:V=A8)),""–""),"""")"),"")
A9: ='Справочник'!E4 | B9: =IF(A9>0,SUMIF('Барабан'!K:K,A9,'Барабан'!I:I),"") | C9: =IF(A9>0,SUMIF('Барабан'!V:V,A9,'Барабан'!T:T),"") | D9: =IF(A9>0,SUMIF('Барабан'!K:K,A9,'Барабан'!AG:AG)+SUMIF('Барабан'!V:V,A9,'Барабан'!AG:AG),"") | E9: =IF(A9>0,ROUND(B9-C9,0),"") | F9: {=IFERROR(IF(E9=0,0,INDEX('Справочник'!G:G,MATCH(A9,'Справочник'!F:F,0))))} | G9: =IF(A9>0,SUMIF('Барабан'!K:K,A9,'Барабан'!P:P),"") | H9: =IF(A9>0,SUMIF('Барабан'!V:V,A9,'Барабан'!AA:AA),"") | I9: =IF(A9>0,H9+F9-G9-D9,"") | J9: =IFERROR(IF(A9>0,I9/G9,""),"–") | K9: =IF(A9>0,COUNTIF('Барабан'!K:K,A9),"") | L9: =IF(A9>0,COUNTIF('Барабан'!V:V,A9),"") | M9: =IF(A9>0,IFERROR(O9-N9,TODAY()-N9),"") | N9: =IFERROR(__xludf.DUMMYFUNCTION("IF(A9>0,MIN(FILTER('Барабан'!AJ:AJ,'Барабан'!K:K=A9)),"""")"),"") | O9: =IFERROR(__xludf.DUMMYFUNCTION("IF(A9>0,IFERROR(MAX(FILTER('Барабан'!AJ:AJ,'Барабан'!V:V=A9)),""–""),"""")"),"")
A10: ='Справочник'!E5 | B10: =IF(A10>0,SUMIF('Барабан'!K:K,A10,'Барабан'!I:I),"") | C10: =IF(A10>0,SUMIF('Барабан'!V:V,A10,'Барабан'!T:T),"") | D10: =IF(A10>0,SUMIF('Барабан'!K:K,A10,'Барабан'!AG:AG)+SUMIF('Барабан'!V:V,A10,'Барабан'!AG:AG),"") | E10: =IF(A10>0,ROUND(B10-C10,0),"") | F10: {=IFERROR(IF(E10=0,0,INDEX('Справочник'!G:G,MATCH(A10,'Справочник'!F:F,0))))} | G10: =IF(A10>0,SUMIF('Барабан'!K:K,A10,'Барабан'!P:P),"") | H10: =IF(A10>0,SUMIF('Барабан'!V:V,A10,'Барабан'!AA:AA),"") | I10: =IF(A10>0,H10+F10-G10-D10,"") | J10: =IFERROR(IF(A10>0,I10/G10,""),"–") | K10: =IF(A10>0,COUNTIF('Барабан'!K:K,A10),"") | L10: =IF(A10>0,COUNTIF('Барабан'!V:V,A10),"") | M10: =IF(A10>0,IFERROR(O10-N10,TODAY()-N10),"") | N10: =IFERROR(__xludf.DUMMYFUNCTION("IF(A10>0,MIN(FILTER('Барабан'!AJ:AJ,'Барабан'!K:K=A10)),"""")"),"") | O10: =IFERROR(__xludf.DUMMYFUNCTION("IF(A10>0,IFERROR(MAX(FILTER('Барабан'!AJ:AJ,'Барабан'!V:V=A10)),""–""),"""")"),"")
A11: ='Справочник'!E6 | B11: =IF(A11>0,SUMIF('Барабан'!K:K,A11,'Барабан'!I:I),"") | C11: =IF(A11>0,SUMIF('Барабан'!V:V,A11,'Барабан'!T:T),"") | D11: =IF(A11>0,SUMIF('Барабан'!K:K,A11,'Барабан'!AG:AG)+SUMIF('Барабан'!V:V,A11,'Барабан'!AG:AG),"") | E11: =IF(A11>0,ROUND(B11-C11,0),"") | F11: {=IFERROR(IF(E11=0,0,INDEX('Справочник'!G:G,MATCH(A11,'Справочник'!F:F,0))))} | G11: =IF(A11>0,SUMIF('Барабан'!K:K,A11,'Барабан'!P:P),"") | H11: =IF(A11>0,SUMIF('Барабан'!V:V,A11,'Барабан'!AA:AA),"") | I11: =IF(A11>0,H11+F11-G11-D11,"") | J11: =IFERROR(IF(A11>0,I11/G11,""),"–") | K11: =IF(A11>0,COUNTIF('Барабан'!K:K,A11),"") | L11: =IF(A11>0,COUNTIF('Барабан'!V:V,A11),"") | M11: =IF(A11>0,IFERROR(O11-N11,TODAY()-N11),"") | N11: =IFERROR(__xludf.DUMMYFUNCTION("IF(A11>0,MIN(FILTER('Барабан'!AJ:AJ,'Барабан'!K:K=A11)),"""")"),"") | O11: =IFERROR(__xludf.DUMMYFUNCTION("IF(A11>0,IFERROR(MAX(FILTER('Барабан'!AJ:AJ,'Барабан'!V:V=A11)),""–""),"""")"),"")
A12: ='Справочник'!E7 | B12: =IF(A12>0,SUMIF('Барабан'!K:K,A12,'Барабан'!I:I),"") | C12: =IF(A12>0,SUMIF('Барабан'!V:V,A12,'Барабан'!T:T),"") | D12: =IF(A12>0,SUMIF('Барабан'!K:K,A12,'Барабан'!AG:AG)+SUMIF('Барабан'!V:V,A12,'Барабан'!AG:AG),"") | E12: =IF(A12>0,ROUND(B12-C12,0),"") | F12: {=IFERROR(IF(E12=0,0,INDEX('Справочник'!G:G,MATCH(A12,'Справочник'!F:F,0))))} | G12: =IF(A12>0,SUMIF('Барабан'!K:K,A12,'Барабан'!P:P),"") | H12: =IF(A12>0,SUMIF('Барабан'!V:V,A12,'Барабан'!AA:AA),"") | I12: =IF(A12>0,H12+F12-G12-D12,"") | J12: =IFERROR(IF(A12>0,I12/G12,""),"–") | K12: =IF(A12>0,COUNTIF('Барабан'!K:K,A12),"") | L12: =IF(A12>0,COUNTIF('Барабан'!V:V,A12),"") | M12: =IF(A12>0,IFERROR(O12-N12,TODAY()-N12),"") | N12: =IFERROR(__xludf.DUMMYFUNCTION("IF(A12>0,MIN(FILTER('Барабан'!AJ:AJ,'Барабан'!K:K=A12)),"""")"),"") | O12: =IFERROR(__xludf.DUMMYFUNCTION("IF(A12>0,IFERROR(MAX(FILTER('Барабан'!AJ:AJ,'Барабан'!V:V=A12)),""–""),"""")"),"")
A13: ='Справочник'!E8 | B13: =IF(A13>0,SUMIF('Барабан'!K:K,A13,'Барабан'!I:I),"") | C13: =IF(A13>0,SUMIF('Барабан'!V:V,A13,'Барабан'!T:T),"") | D13: =IF(A13>0,SUMIF('Барабан'!K:K,A13,'Барабан'!AG:AG)+SUMIF('Барабан'!V:V,A13,'Барабан'!AG:AG),"") | E13: =IF(A13>0,ROUND(B13-C13,0),"") | F13: {=IFERROR(IF(E13=0,0,INDEX('Справочник'!G:G,MATCH(A13,'Справочник'!F:F,0))))} | G13: =IF(A13>0,SUMIF('Барабан'!K:K,A13,'Барабан'!P:P),"") | H13: =IF(A13>0,SUMIF('Барабан'!V:V,A13,'Барабан'!AA:AA),"") | I13: =IF(A13>0,H13+F13-G13-D13,"") | J13: =IFERROR(IF(A13>0,I13/G13,""),"–") | K13: =IF(A13>0,COUNTIF('Барабан'!K:K,A13),"") | L13: =IF(A13>0,COUNTIF('Барабан'!V:V,A13),"") | M13: =IF(A13>0,IFERROR(O13-N13,TODAY()-N13),"") | N13: =IFERROR(__xludf.DUMMYFUNCTION("IF(A13>0,MIN(FILTER('Барабан'!AJ:AJ,'Барабан'!K:K=A13)),"""")"),"") | O13: =IFERROR(__xludf.DUMMYFUNCTION("IF(A13>0,IFERROR(MAX(FILTER('Барабан'!AJ:AJ,'Барабан'!V:V=A13)),""–""),"""")"),"")
A14: ='Справочник'!E9 | B14: =IF(A14>0,SUMIF('Барабан'!K:K,A14,'Барабан'!I:I),"") | C14: =IF(A14>0,SUMIF('Барабан'!V:V,A14,'Барабан'!T:T),"") | D14: =IF(A14>0,SUMIF('Барабан'!K:K,A14,'Барабан'!AG:AG)+SUMIF('Барабан'!V:V,A14,'Барабан'!AG:AG),"") | E14: =IF(A14>0,ROUND(B14-C14,0),"") | F14: {=IFERROR(IF(E14=0,0,INDEX('Справочник'!G:G,MATCH(A14,'Справочник'!F:F,0))))} | G14: =IF(A14>0,SUMIF('Барабан'!K:K,A14,'Барабан'!P:P),"") | H14: =IF(A14>0,SUMIF('Барабан'!V:V,A14,'Барабан'!AA:AA),"") | I14: =IF(A14>0,H14+F14-G14-D14,"") | J14: =IFERROR(IF(A14>0,I14/G14,""),"–") | K14: =IF(A14>0,COUNTIF('Барабан'!K:K,A14),"") | L14: =IF(A14>0,COUNTIF('Барабан'!V:V,A14),"") | M14: =IF(A14>0,IFERROR(O14-N14,TODAY()-N14),"") | N14: =IFERROR(__xludf.DUMMYFUNCTION("IF(A14>0,MIN(FILTER('Барабан'!AJ:AJ,'Барабан'!K:K=A14)),"""")"),"") | O14: =IFERROR(__xludf.DUMMYFUNCTION("IF(A14>0,IFERROR(MAX(FILTER('Барабан'!AJ:AJ,'Барабан'!V:V=A14)),""–""),"""")"),"")
A15: ='Справочник'!E10 | B15: =IF(A15>0,SUMIF('Барабан'!K:K,A15,'Барабан'!I:I),"") | C15: =IF(A15>0,SUMIF('Барабан'!V:V,A15,'Барабан'!T:T),"") | D15: =IF(A15>0,SUMIF('Барабан'!K:K,A15,'Барабан'!AG:AG)+SUMIF('Барабан'!V:V,A15,'Барабан'!AG:AG),"") | E15: =IF(A15>0,ROUND(B15-C15,0),"") | F15: {=IFERROR(IF(E15=0,0,INDEX('Справочник'!G:G,MATCH(A15,'Справочник'!F:F,0))))} | G15: =IF(A15>0,SUMIF('Барабан'!K:K,A15,'Барабан'!P:P),"") | H15: =IF(A15>0,SUMIF('Барабан'!V:V,A15,'Барабан'!AA:AA),"") | I15: =IF(A15>0,H15+F15-G15-D15,"") | J15: =IFERROR(IF(A15>0,I15/G15,""),"–") | K15: =IF(A15>0,COUNTIF('Барабан'!K:K,A15),"") | L15: =IF(A15>0,COUNTIF('Барабан'!V:V,A15),"") | M15: =IF(A15>0,IFERROR(O15-N15,TODAY()-N15),"") | N15: =IFERROR(__xludf.DUMMYFUNCTION("IF(A15>0,MIN(FILTER('Барабан'!AJ:AJ,'Барабан'!K:K=A15)),"""")"),"") | O15: =IFERROR(__xludf.DUMMYFUNCTION("IF(A15>0,IFERROR(MAX(FILTER('Барабан'!AJ:AJ,'Барабан'!V:V=A15)),""–""),"""")"),"")
A16: ='Справочник'!E11 | B16: =IF(A16>0,SUMIF('Барабан'!K:K,A16,'Барабан'!I:I),"") | C16: =IF(A16>0,SUMIF('Барабан'!V:V,A16,'Барабан'!T:T),"") | D16: =IF(A16>0,SUMIF('Барабан'!K:K,A16,'Барабан'!AG:AG)+SUMIF('Барабан'!V:V,A16,'Барабан'!AG:AG),"") | E16: =IF(A16>0,ROUND(B16-C16,0),"") | F16: {=IFERROR(IF(E16=0,0,INDEX('Справочник'!G:G,MATCH(A16,'Справочник'!F:F,0))))} | G16: =IF(A16>0,SUMIF('Барабан'!K:K,A16,'Барабан'!P:P),"") | H16: =IF(A16>0,SUMIF('Барабан'!V:V,A16,'Барабан'!AA:AA),"") | I16: =IF(A16>0,H16+F16-G16-D16,"") | J16: =IFERROR(IF(A16>0,I16/G16,""),"–") | K16: =IF(A16>0,COUNTIF('Барабан'!K:K,A16),"") | L16: =IF(A16>0,COUNTIF('Барабан'!V:V,A16),"") | M16: =IF(A16>0,IFERROR(O16-N16,TODAY()-N16),"") | N16: =IFERROR(__xludf.DUMMYFUNCTION("IF(A16>0,MIN(FILTER('Барабан'!AJ:AJ,'Барабан'!K:K=A16)),"""")"),"") | O16: =IFERROR(__xludf.DUMMYFUNCTION("IF(A16>0,IFERROR(MAX(FILTER('Барабан'!AJ:AJ,'Барабан'!V:V=A16)),""–""),"""")"),"")
A17: ='Справочник'!E12 | B17: =IF(A17>0,SUMIF('Барабан'!K:K,A17,'Барабан'!I:I),"") | C17: =IF(A17>0,SUMIF('Барабан'!V:V,A17,'Барабан'!T:T),"") | D17: =IF(A17>0,SUMIF('Барабан'!K:K,A17,'Барабан'!AG:AG)+SUMIF('Барабан'!V:V,A17,'Барабан'!AG:AG),"") | E17: =IF(A17>0,ROUND(B17-C17,0),"") | F17: {=IFERROR(IF(E17=0,0,INDEX('Справочник'!G:G,MATCH(A17,'Справочник'!F:F,0))))} | G17: =IF(A17>0,SUMIF('Барабан'!K:K,A17,'Барабан'!P:P),"") | H17: =IF(A17>0,SUMIF('Барабан'!V:V,A17,'Барабан'!AA:AA),"") | I17: =IF(A17>0,H17+F17-G17-D17,"") | J17: =IFERROR(IF(A17>0,I17/G17,""),"–") | K17: =IF(A17>0,COUNTIF('Барабан'!K:K,A17),"") | L17: =IF(A17>0,COUNTIF('Барабан'!V:V,A17),"") | M17: =IF(A17>0,IFERROR(O17-N17,TODAY()-N17),"") | N17: =IFERROR(__xludf.DUMMYFUNCTION("IF(A17>0,MIN(FILTER('Барабан'!AJ:AJ,'Барабан'!K:K=A17)),"""")"),"") | O17: =IFERROR(__xludf.DUMMYFUNCTION("IF(A17>0,IFERROR(MAX(FILTER('Барабан'!AJ:AJ,'Барабан'!V:V=A17)),""–""),"""")"),"")
A18: ='Справочник'!E13 | B18: =IF(A18>0,SUMIF('Барабан'!K:K,A18,'Барабан'!I:I),"") | C18: =IF(A18>0,SUMIF('Барабан'!V:V,A18,'Барабан'!T:T),"") | D18: =IF(A18>0,SUMIF('Барабан'!K:K,A18,'Барабан'!AG:AG)+SUMIF('Барабан'!V:V,A18,'Барабан'!AG:AG),"") | E18: =IF(A18>0,ROUND(B18-C18,0),"") | F18: {=IFERROR(IF(E18=0,0,INDEX('Справочник'!G:G,MATCH(A18,'Справочник'!F:F,0))))} | G18: =IF(A18>0,SUMIF('Барабан'!K:K,A18,'Барабан'!P:P),"") | H18: =IF(A18>0,SUMIF('Барабан'!V:V,A18,'Барабан'!AA:AA),"") | I18: =IF(A18>0,H18+F18-G18-D18,"") | J18: =IFERROR(IF(A18>0,I18/G18,""),"–") | K18: =IF(A18>0,COUNTIF('Барабан'!K:K,A18),"") | L18: =IF(A18>0,COUNTIF('Барабан'!V:V,A18),"") | M18: =IF(A18>0,IFERROR(O18-N18,TODAY()-N18),"") | N18: =IFERROR(__xludf.DUMMYFUNCTION("IF(A18>0,MIN(FILTER('Барабан'!AJ:AJ,'Барабан'!K:K=A18)),"""")"),"") | O18: =IFERROR(__xludf.DUMMYFUNCTION("IF(A18>0,IFERROR(MAX(FILTER('Барабан'!AJ:AJ,'Барабан'!V:V=A18)),""–""),"""")"),"")
A19: ='Справочник'!E14 | B19: =IF(A19>0,SUMIF('Барабан'!K:K,A19,'Барабан'!I:I),"") | C19: =IF(A19>0,SUMIF('Барабан'!V:V,A19,'Барабан'!T:T),"") | D19: =IF(A19>0,SUMIF('Барабан'!K:K,A19,'Барабан'!AG:AG)+SUMIF('Барабан'!V:V,A19,'Барабан'!AG:AG),"") | E19: =IF(A19>0,ROUND(B19-C19,0),"") | F19: {=IFERROR(IF(E19=0,0,INDEX('Справочник'!G:G,MATCH(A19,'Справочник'!F:F,0))))} | G19: =IF(A19>0,SUMIF('Барабан'!K:K,A19,'Барабан'!P:P),"") | H19: =IF(A19>0,SUMIF('Барабан'!V:V,A19,'Барабан'!AA:AA),"") | I19: =IF(A19>0,H19+F19-G19-D19,"") | J19: =IFERROR(IF(A19>0,I19/G19,""),"–") | K19: =IF(A19>0,COUNTIF('Барабан'!K:K,A19),"") | L19: =IF(A19>0,COUNTIF('Барабан'!V:V,A19),"") | M19: =IF(A19>0,IFERROR(O19-N19,TODAY()-N19),"") | N19: =IFERROR(__xludf.DUMMYFUNCTION("IF(A19>0,MIN(FILTER('Барабан'!AJ:AJ,'Барабан'!K:K=A19)),"""")"),"") | O19: =IFERROR(__xludf.DUMMYFUNCTION("IF(A19>0,IFERROR(MAX(FILTER('Барабан'!AJ:AJ,'Барабан'!V:V=A19)),""–""),"""")"),"")
A20: ='Справочник'!E15 | B20: =IF(A20>0,SUMIF('Барабан'!K:K,A20,'Барабан'!I:I),"") | C20: =IF(A20>0,SUMIF('Барабан'!V:V,A20,'Барабан'!T:T),"") | D20: =IF(A20>0,SUMIF('Барабан'!K:K,A20,'Барабан'!AG:AG)+SUMIF('Барабан'!V:V,A20,'Барабан'!AG:AG),"") | E20: =IF(A20>0,ROUND(B20-C20,0),"") | F20: {=IFERROR(IF(E20=0,0,INDEX('Справочник'!G:G,MATCH(A20,'Справочник'!F:F,0))))} | G20: =IF(A20>0,SUMIF('Барабан'!K:K,A20,'Барабан'!P:P),"") | H20: =IF(A20>0,SUMIF('Барабан'!V:V,A20,'Барабан'!AA:AA),"") | I20: =IF(A20>0,H20+F20-G20-D20,"") | J20: =IFERROR(IF(A20>0,I20/G20,""),"–") | K20: =IF(A20>0,COUNTIF('Барабан'!K:K,A20),"") | L20: =IF(A20>0,COUNTIF('Барабан'!V:V,A20),"") | M20: =IF(A20>0,IFERROR(O20-N20,TODAY()-N20),"") | N20: =IFERROR(__xludf.DUMMYFUNCTION("IF(A20>0,MIN(FILTER('Барабан'!AJ:AJ,'Барабан'!K:K=A20)),"""")"),"") | O20: =IFERROR(__xludf.DUMMYFUNCTION("IF(A20>0,IFERROR(MAX(FILTER('Барабан'!AJ:AJ,'Барабан'!V:V=A20)),""–""),"""")"),"")
A21: ='Справочник'!E16 | B21: =IF(A21>0,SUMIF('Барабан'!K:K,A21,'Барабан'!I:I),"") | C21: =IF(A21>0,SUMIF('Барабан'!V:V,A21,'Барабан'!T:T),"") | D21: =IF(A21>0,SUMIF('Барабан'!K:K,A21,'Барабан'!AG:AG)+SUMIF('Барабан'!V:V,A21,'Барабан'!AG:AG),"") | E21: =IF(A21>0,ROUND(B21-C21,0),"") | F21: {=IFERROR(IF(E21=0,0,INDEX('Справочник'!G:G,MATCH(A21,'Справочник'!F:F,0))))} | G21: =IF(A21>0,SUMIF('Барабан'!K:K,A21,'Барабан'!P:P),"") | H21: =IF(A21>0,SUMIF('Барабан'!V:V,A21,'Барабан'!AA:AA),"") | I21: =IF(A21>0,H21+F21-G21-D21,"") | J21: =IFERROR(IF(A21>0,I21/G21,""),"–") | K21: =IF(A21>0,COUNTIF('Барабан'!K:K,A21),"") | L21: =IF(A21>0,COUNTIF('Барабан'!V:V,A21),"") | M21: =IF(A21>0,IFERROR(O21-N21,TODAY()-N21),"") | N21: =IFERROR(__xludf.DUMMYFUNCTION("IF(A21>0,MIN(FILTER('Барабан'!AJ:AJ,'Барабан'!K:K=A21)),"""")"),"") | O21: =IFERROR(__xludf.DUMMYFUNCTION("IF(A21>0,IFERROR(MAX(FILTER('Барабан'!AJ:AJ,'Барабан'!V:V=A21)),""–""),"""")"),"")
A22: ='Справочник'!E17 | B22: =IF(A22>0,SUMIF('Барабан'!K:K,A22,'Барабан'!I:I),"") | C22: =IF(A22>0,SUMIF('Барабан'!V:V,A22,'Барабан'!T:T),"") | D22: =IF(A22>0,SUMIF('Барабан'!K:K,A22,'Барабан'!AG:AG)+SUMIF('Барабан'!V:V,A22,'Барабан'!AG:AG),"") | E22: =IF(A22>0,ROUND(B22-C22,0),"") | F22: {=IFERROR(IF(E22=0,0,INDEX('Справочник'!G:G,MATCH(A22,'Справочник'!F:F,0))))} | G22: =IF(A22>0,SUMIF('Барабан'!K:K,A22,'Барабан'!P:P),"") | H22: =IF(A22>0,SUMIF('Барабан'!V:V,A22,'Барабан'!AA:AA),"") | I22: =IF(A22>0,H22+F22-G22-D22,"") | J22: =IFERROR(IF(A22>0,I22/G22,""),"–") | K22: =IF(A22>0,COUNTIF('Барабан'!K:K,A22),"") | L22: =IF(A22>0,COUNTIF('Барабан'!V:V,A22),"") | M22: =IF(A22>0,IFERROR(O22-N22,TODAY()-N22),"") | N22: =IFERROR(__xludf.DUMMYFUNCTION("IF(A22>0,MIN(FILTER('Барабан'!AJ:AJ,'Барабан'!K:K=A22)),"""")"),"") | O22: =IFERROR(__xludf.DUMMYFUNCTION("IF(A22>0,IFERROR(MAX(FILTER('Барабан'!AJ:AJ,'Барабан'!V:V=A22)),""–""),"""")"),"")
A23: ='Справочник'!E18 | B23: =IF(A23>0,SUMIF('Барабан'!K:K,A23,'Барабан'!I:I),"") | C23: =IF(A23>0,SUMIF('Барабан'!V:V,A23,'Барабан'!T:T),"") | D23: =IF(A23>0,SUMIF('Барабан'!K:K,A23,'Барабан'!AG:AG)+SUMIF('Барабан'!V:V,A23,'Барабан'!AG:AG),"") | E23: =IF(A23>0,ROUND(B23-C23,0),"") | F23: {=IFERROR(IF(E23=0,0,INDEX('Справочник'!G:G,MATCH(A23,'Справочник'!F:F,0))))} | G23: =IF(A23>0,SUMIF('Барабан'!K:K,A23,'Барабан'!P:P),"") | H23: =IF(A23>0,SUMIF('Барабан'!V:V,A23,'Барабан'!AA:AA),"") | I23: =IF(A23>0,H23+F23-G23-D23,"") | J23: =IFERROR(IF(A23>0,I23/G23,""),"–") | K23: =IF(A23>0,COUNTIF('Барабан'!K:K,A23),"") | L23: =IF(A23>0,COUNTIF('Барабан'!V:V,A23),"") | M23: =IF(A23>0,IFERROR(O23-N23,TODAY()-N23),"") | N23: =IFERROR(__xludf.DUMMYFUNCTION("IF(A23>0,MIN(FILTER('Барабан'!AJ:AJ,'Барабан'!K:K=A23)),"""")"),"") | O23: =IFERROR(__xludf.DUMMYFUNCTION("IF(A23>0,IFERROR(MAX(FILTER('Барабан'!AJ:AJ,'Барабан'!V:V=A23)),""–""),"""")"),"")
A24: ='Справочник'!E19 | B24: =IF(A24>0,SUMIF('Барабан'!K:K,A24,'Барабан'!I:I),"") | C24: =IF(A24>0,SUMIF('Барабан'!V:V,A24,'Барабан'!T:T),"") | D24: =IF(A24>0,SUMIF('Барабан'!K:K,A24,'Барабан'!AG:AG)+SUMIF('Барабан'!V:V,A24,'Барабан'!AG:AG),"") | E24: =IF(A24>0,ROUND(B24-C24,0),"") | F24: {=IFERROR(IF(E24=0,0,INDEX('Справочник'!G:G,MATCH(A24,'Справочник'!F:F,0))))} | G24: =IF(A24>0,SUMIF('Барабан'!K:K,A24,'Барабан'!P:P),"") | H24: =IF(A24>0,SUMIF('Барабан'!V:V,A24,'Барабан'!AA:AA),"") | I24: =IF(A24>0,H24+F24-G24-D24,"") | J24: =IFERROR(IF(A24>0,I24/G24,""),"–") | K24: =IF(A24>0,COUNTIF('Барабан'!K:K,A24),"") | L24: =IF(A24>0,COUNTIF('Барабан'!V:V,A24),"") | M24: =IF(A24>0,IFERROR(O24-N24,TODAY()-N24),"") | N24: =IFERROR(__xludf.DUMMYFUNCTION("IF(A24>0,MIN(FILTER('Барабан'!AJ:AJ,'Барабан'!K:K=A24)),"""")"),"") | O24: =IFERROR(__xludf.DUMMYFUNCTION("IF(A24>0,IFERROR(MAX(FILTER('Барабан'!AJ:AJ,'Барабан'!V:V=A24)),""–""),"""")"),"")
A25: ='Справочник'!E20 | B25: =IF(A25>0,SUMIF('Барабан'!K:K,A25,'Барабан'!I:I),"") | C25: =IF(A25>0,SUMIF('Барабан'!V:V,A25,'Барабан'!T:T),"") | D25: =IF(A25>0,SUMIF('Барабан'!K:K,A25,'Барабан'!AG:AG)+SUMIF('Барабан'!V:V,A25,'Барабан'!AG:AG),"") | E25: =IF(A25>0,ROUND(B25-C25,0),"") | F25: {=IFERROR(IF(E25=0,0,INDEX('Справочник'!G:G,MATCH(A25,'Справочник'!F:F,0))))} | G25: =IF(A25>0,SUMIF('Барабан'!K:K,A25,'Барабан'!P:P),"") | H25: =IF(A25>0,SUMIF('Барабан'!V:V,A25,'Барабан'!AA:AA),"") | I25: =IF(A25>0,H25+F25-G25-D25,"") | J25: =IFERROR(IF(A25>0,I25/G25,""),"–") | K25: =IF(A25>0,COUNTIF('Барабан'!K:K,A25),"") | L25: =IF(A25>0,COUNTIF('Барабан'!V:V,A25),"") | M25: =IF(A25>0,IFERROR(O25-N25,TODAY()-N25),"") | N25: =IFERROR(__xludf.DUMMYFUNCTION("IF(A25>0,MIN(FILTER('Барабан'!AJ:AJ,'Барабан'!K:K=A25)),"""")"),"") | O25: =IFERROR(__xludf.DUMMYFUNCTION("IF(A25>0,IFERROR(MAX(FILTER('Барабан'!AJ:AJ,'Барабан'!V:V=A25)),""–""),"""")"),"")
A26: ='Справочник'!E21 | B26: =IF(A26>0,SUMIF('Барабан'!K:K,A26,'Барабан'!I:I),"") | C26: =IF(A26>0,SUMIF('Барабан'!V:V,A26,'Барабан'!T:T),"") | D26: =IF(A26>0,SUMIF('Барабан'!K:K,A26,'Барабан'!AG:AG)+SUMIF('Барабан'!V:V,A26,'Барабан'!AG:AG),"") | E26: =IF(A26>0,ROUND(B26-C26,0),"") | F26: {=IFERROR(IF(E26=0,0,INDEX('Справочник'!G:G,MATCH(A26,'Справочник'!F:F,0))))} | G26: =IF(A26>0,SUMIF('Барабан'!K:K,A26,'Барабан'!P:P),"") | H26: =IF(A26>0,SUMIF('Барабан'!V:V,A26,'Барабан'!AA:AA),"") | I26: =IF(A26>0,H26+F26-G26-D26,"") | J26: =IFERROR(IF(A26>0,I26/G26,""),"–") | K26: =IF(A26>0,COUNTIF('Барабан'!K:K,A26),"") | L26: =IF(A26>0,COUNTIF('Барабан'!V:V,A26),"") | M26: =IF(A26>0,IFERROR(O26-N26,TODAY()-N26),"") | N26: =IFERROR(__xludf.DUMMYFUNCTION("IF(A26>0,MIN(FILTER('Барабан'!AJ:AJ,'Барабан'!K:K=A26)),"""")"),"") | O26: =IFERROR(__xludf.DUMMYFUNCTION("IF(A26>0,IFERROR(MAX(FILTER('Барабан'!AJ:AJ,'Барабан'!V:V=A26)),""–""),"""")"),"")
A27: ='Справочник'!E22 | B27: =IF(A27>0,SUMIF('Барабан'!K:K,A27,'Барабан'!I:I),"") | C27: =IF(A27>0,SUMIF('Барабан'!V:V,A27,'Барабан'!T:T),"") | D27: =IF(A27>0,SUMIF('Барабан'!K:K,A27,'Барабан'!AG:AG)+SUMIF('Барабан'!V:V,A27,'Барабан'!AG:AG),"") | E27: =IF(A27>0,ROUND(B27-C27,0),"") | F27: {=IFERROR(IF(E27=0,0,INDEX('Справочник'!G:G,MATCH(A27,'Справочник'!F:F,0))))} | G27: =IF(A27>0,SUMIF('Барабан'!K:K,A27,'Барабан'!P:P),"") | H27: =IF(A27>0,SUMIF('Барабан'!V:V,A27,'Барабан'!AA:AA),"") | I27: =IF(A27>0,H27+F27-G27-D27,"") | J27: =IFERROR(IF(A27>0,I27/G27,""),"–") | K27: =IF(A27>0,COUNTIF('Барабан'!K:K,A27),"") | L27: =IF(A27>0,COUNTIF('Барабан'!V:V,A27),"") | M27: =IF(A27>0,IFERROR(O27-N27,TODAY()-N27),"") | N27: =IFERROR(__xludf.DUMMYFUNCTION("IF(A27>0,MIN(FILTER('Барабан'!AJ:AJ,'Барабан'!K:K=A27)),"""")"),"") | O27: =IFERROR(__xludf.DUMMYFUNCTION("IF(A27>0,IFERROR(MAX(FILTER('Барабан'!AJ:AJ,'Барабан'!V:V=A27)),""–""),"""")"),"")
A28: ='Справочник'!E23 | B28: =IF(A28>0,SUMIF('Барабан'!K:K,A28,'Барабан'!I:I),"") | C28: =IF(A28>0,SUMIF('Барабан'!V:V,A28,'Барабан'!T:T),"") | D28: =IF(A28>0,SUMIF('Барабан'!K:K,A28,'Барабан'!AG:AG)+SUMIF('Барабан'!V:V,A28,'Барабан'!AG:AG),"") | E28: =IF(A28>0,ROUND(B28-C28,0),"") | F28: {=IFERROR(IF(E28=0,0,INDEX('Справочник'!G:G,MATCH(A28,'Справочник'!F:F,0))))} | G28: =IF(A28>0,SUMIF('Барабан'!K:K,A28,'Барабан'!P:P),"") | H28: =IF(A28>0,SUMIF('Барабан'!V:V,A28,'Барабан'!AA:AA),"") | I28: =IF(A28>0,H28+F28-G28-D28,"") | J28: =IFERROR(IF(A28>0,I28/G28,""),"–") | K28: =IF(A28>0,COUNTIF('Барабан'!K:K,A28),"") | L28: =IF(A28>0,COUNTIF('Барабан'!V:V,A28),"") | M28: =IF(A28>0,IFERROR(O28-N28,TODAY()-N28),"") | N28: =IFERROR(__xludf.DUMMYFUNCTION("IF(A28>0,MIN(FILTER('Барабан'!AJ:AJ,'Барабан'!K:K=A28)),"""")"),"") | O28: =IFERROR(__xludf.DUMMYFUNCTION("IF(A28>0,IFERROR(MAX(FILTER('Барабан'!AJ:AJ,'Барабан'!V:V=A28)),""–""),"""")"),"")
A29: ='Справочник'!E24 | B29: =IF(A29>0,SUMIF('Барабан'!K:K,A29,'Барабан'!I:I),"") | C29: =IF(A29>0,SUMIF('Барабан'!V:V,A29,'Барабан'!T:T),"") | D29: =IF(A29>0,SUMIF('Барабан'!K:K,A29,'Барабан'!AG:AG)+SUMIF('Барабан'!V:V,A29,'Барабан'!AG:AG),"") | E29: =IF(A29>0,ROUND(B29-C29,0),"") | F29: {=IFERROR(IF(E29=0,0,INDEX('Справочник'!G:G,MATCH(A29,'Справочник'!F:F,0))))} | G29: =IF(A29>0,SUMIF('Барабан'!K:K,A29,'Барабан'!P:P),"") | H29: =IF(A29>0,SUMIF('Барабан'!V:V,A29,'Барабан'!AA:AA),"") | I29: =IF(A29>0,H29+F29-G29-D29,"") | J29: =IFERROR(IF(A29>0,I29/G29,""),"–") | K29: =IF(A29>0,COUNTIF('Барабан'!K:K,A29),"") | L29: =IF(A29>0,COUNTIF('Барабан'!V:V,A29),"") | M29: =IF(A29>0,IFERROR(O29-N29,TODAY()-N29),"") | N29: =IFERROR(__xludf.DUMMYFUNCTION("IF(A29>0,MIN(FILTER('Барабан'!AJ:AJ,'Барабан'!K:K=A29)),"""")"),"") | O29: =IFERROR(__xludf.DUMMYFUNCTION("IF(A29>0,IFERROR(MAX(FILTER('Барабан'!AJ:AJ,'Барабан'!V:V=A29)),""–""),"""")"),"")
A30: ='Справочник'!E25 | B30: =IF(A30>0,SUMIF('Барабан'!K:K,A30,'Барабан'!I:I),"") | C30: =IF(A30>0,SUMIF('Барабан'!V:V,A30,'Барабан'!T:T),"") | D30: =IF(A30>0,SUMIF('Барабан'!K:K,A30,'Барабан'!AG:AG)+SUMIF('Барабан'!V:V,A30,'Барабан'!AG:AG),"") | E30: =IF(A30>0,ROUND(B30-C30,0),"") | F30: {=IFERROR(IF(E30=0,0,INDEX('Справочник'!G:G,MATCH(A30,'Справочник'!F:F,0))))} | G30: =IF(A30>0,SUMIF('Барабан'!K:K,A30,'Барабан'!P:P),"") | H30: =IF(A30>0,SUMIF('Барабан'!V:V,A30,'Барабан'!AA:AA),"") | I30: =IF(A30>0,H30+F30-G30-D30,"") | J30: =IFERROR(IF(A30>0,I30/G30,""),"–") | K30: =IF(A30>0,COUNTIF('Барабан'!K:K,A30),"") | L30: =IF(A30>0,COUNTIF('Барабан'!V:V,A30),"") | M30: =IF(A30>0,IFERROR(O30-N30,TODAY()-N30),"") | N30: =IFERROR(__xludf.DUMMYFUNCTION("IF(A30>0,MIN(FILTER('Барабан'!AJ:AJ,'Барабан'!K:K=A30)),"""")"),"") | O30: =IFERROR(__xludf.DUMMYFUNCTION("IF(A30>0,IFERROR(MAX(FILTER('Барабан'!AJ:AJ,'Барабан'!V:V=A30)),""–""),"""")"),"")
A31: ='Справочник'!E26 | B31: =IF(A31>0,SUMIF('Барабан'!K:K,A31,'Барабан'!I:I),"") | C31: =IF(A31>0,SUMIF('Барабан'!V:V,A31,'Барабан'!T:T),"") | D31: =IF(A31>0,SUMIF('Барабан'!K:K,A31,'Барабан'!AG:AG)+SUMIF('Барабан'!V:V,A31,'Барабан'!AG:AG),"") | E31: =IF(A31>0,ROUND(B31-C31,0),"") | F31: {=IFERROR(IF(E31=0,0,INDEX('Справочник'!G:G,MATCH(A31,'Справочник'!F:F,0))))} | G31: =IF(A31>0,SUMIF('Барабан'!K:K,A31,'Барабан'!P:P),"") | H31: =IF(A31>0,SUMIF('Барабан'!V:V,A31,'Барабан'!AA:AA),"") | I31: =IF(A31>0,H31+F31-G31-D31,"") | J31: =IFERROR(IF(A31>0,I31/G31,""),"–") | K31: =IF(A31>0,COUNTIF('Барабан'!K:K,A31),"") | L31: =IF(A31>0,COUNTIF('Барабан'!V:V,A31),"") | M31: =IF(A31>0,IFERROR(O31-N31,TODAY()-N31),"") | N31: =IFERROR(__xludf.DUMMYFUNCTION("IF(A31>0,MIN(FILTER('Барабан'!AJ:AJ,'Барабан'!K:K=A31)),"""")"),"") | O31: =IFERROR(__xludf.DUMMYFUNCTION("IF(A31>0,IFERROR(MAX(FILTER('Барабан'!AJ:AJ,'Барабан'!V:V=A31)),""–""),"""")"),"")
A32: ='Справочник'!E27 | B32: =IF(A32>0,SUMIF('Барабан'!K:K,A32,'Барабан'!I:I),"") | C32: =IF(A32>0,SUMIF('Барабан'!V:V,A32,'Барабан'!T:T),"") | D32: =IF(A32>0,SUMIF('Барабан'!K:K,A32,'Барабан'!AG:AG)+SUMIF('Барабан'!V:V,A32,'Барабан'!AG:AG),"") | E32: =IF(A32>0,ROUND(B32-C32,0),"") | F32: {=IFERROR(IF(E32=0,0,INDEX('Справочник'!G:G,MATCH(A32,'Справочник'!F:F,0))))} | G32: =IF(A32>0,SUMIF('Барабан'!K:K,A32,'Барабан'!P:P),"") | H32: =IF(A32>0,SUMIF('Барабан'!V:V,A32,'Барабан'!AA:AA),"") | I32: =IF(A32>0,H32+F32-G32-D32,"") | J32: =IFERROR(IF(A32>0,I32/G32,""),"–") | K32: =IF(A32>0,COUNTIF('Барабан'!K:K,A32),"") | L32: =IF(A32>0,COUNTIF('Барабан'!V:V,A32),"") | M32: =IF(A32>0,IFERROR(O32-N32,TODAY()-N32),"") | N32: =IFERROR(__xludf.DUMMYFUNCTION("IF(A32>0,MIN(FILTER('Барабан'!AJ:AJ,'Барабан'!K:K=A32)),"""")"),"") | O32: =IFERROR(__xludf.DUMMYFUNCTION("IF(A32>0,IFERROR(MAX(FILTER('Барабан'!AJ:AJ,'Барабан'!V:V=A32)),""–""),"""")"),"")
A33: ='Справочник'!E28 | B33: =IF(A33>0,SUMIF('Барабан'!K:K,A33,'Барабан'!I:I),"") | C33: =IF(A33>0,SUMIF('Барабан'!V:V,A33,'Барабан'!T:T),"") | D33: =IF(A33>0,SUMIF('Барабан'!K:K,A33,'Барабан'!AG:AG)+SUMIF('Барабан'!V:V,A33,'Барабан'!AG:AG),"") | E33: =IF(A33>0,ROUND(B33-C33,0),"") | F33: {=IFERROR(IF(E33=0,0,INDEX('Справочник'!G:G,MATCH(A33,'Справочник'!F:F,0))))} | G33: =IF(A33>0,SUMIF('Барабан'!K:K,A33,'Барабан'!P:P),"") | H33: =IF(A33>0,SUMIF('Барабан'!V:V,A33,'Барабан'!AA:AA),"") | I33: =IF(A33>0,H33+F33-G33-D33,"") | J33: =IFERROR(IF(A33>0,I33/G33,""),"–") | K33: =IF(A33>0,COUNTIF('Барабан'!K:K,A33),"") | L33: =IF(A33>0,COUNTIF('Барабан'!V:V,A33),"") | M33: =IF(A33>0,IFERROR(O33-N33,TODAY()-N33),"") | N33: =IFERROR(__xludf.DUMMYFUNCTION("IF(A33>0,MIN(FILTER('Барабан'!AJ:AJ,'Барабан'!K:K=A33)),"""")"),"") | O33: =IFERROR(__xludf.DUMMYFUNCTION("IF(A33>0,IFERROR(MAX(FILTER('Барабан'!AJ:AJ,'Барабан'!V:V=A33)),""–""),"""")"),"")
A34: ='Справочник'!E29 | B34: =IF(A34>0,SUMIF('Барабан'!K:K,A34,'Барабан'!I:I),"") | C34: =IF(A34>0,SUMIF('Барабан'!V:V,A34,'Барабан'!T:T),"") | D34: =IF(A34>0,SUMIF('Барабан'!K:K,A34,'Барабан'!AG:AG)+SUMIF('Барабан'!V:V,A34,'Барабан'!AG:AG),"") | E34: =IF(A34>0,ROUND(B34-C34,0),"") | F34: {=IFERROR(IF(E34=0,0,INDEX('Справочник'!G:G,MATCH(A34,'Справочник'!F:F,0))))} | G34: =IF(A34>0,SUMIF('Барабан'!K:K,A34,'Барабан'!P:P),"") | H34: =IF(A34>0,SUMIF('Барабан'!V:V,A34,'Барабан'!AA:AA),"") | I34: =IF(A34>0,H34+F34-G34-D34,"") | J34: =IFERROR(IF(A34>0,I34/G34,""),"–") | K34: =IF(A34>0,COUNTIF('Барабан'!K:K,A34),"") | L34: =IF(A34>0,COUNTIF('Барабан'!V:V,A34),"") | M34: =IF(A34>0,IFERROR(O34-N34,TODAY()-N34),"") | N34: =IFERROR(__xludf.DUMMYFUNCTION("IF(A34>0,MIN(FILTER('Барабан'!AJ:AJ,'Барабан'!K:K=A34)),"""")"),"") | O34: =IFERROR(__xludf.DUMMYFUNCTION("IF(A34>0,IFERROR(MAX(FILTER('Барабан'!AJ:AJ,'Барабан'!V:V=A34)),""–""),"""")"),"")
A35: ='Справочник'!E30 | B35: =IF(A35>0,SUMIF('Барабан'!K:K,A35,'Барабан'!I:I),"") | C35: =IF(A35>0,SUMIF('Барабан'!V:V,A35,'Барабан'!T:T),"") | D35: =IF(A35>0,SUMIF('Барабан'!K:K,A35,'Барабан'!AG:AG)+SUMIF('Барабан'!V:V,A35,'Барабан'!AG:AG),"") | E35: =IF(A35>0,ROUND(B35-C35,0),"") | F35: {=IFERROR(IF(E35=0,0,INDEX('Справочник'!G:G,MATCH(A35,'Справочник'!F:F,0))))} | G35: =IF(A35>0,SUMIF('Барабан'!K:K,A35,'Барабан'!P:P),"") | H35: =IF(A35>0,SUMIF('Барабан'!V:V,A35,'Барабан'!AA:AA),"") | I35: =IF(A35>0,H35+F35-G35-D35,"") | J35: =IFERROR(IF(A35>0,I35/G35,""),"–") | K35: =IF(A35>0,COUNTIF('Барабан'!K:K,A35),"") | L35: =IF(A35>0,COUNTIF('Барабан'!V:V,A35),"") | M35: =IF(A35>0,IFERROR(O35-N35,TODAY()-N35),"") | N35: =IFERROR(__xludf.DUMMYFUNCTION("IF(A35>0,MIN(FILTER('Барабан'!AJ:AJ,'Барабан'!K:K=A35)),"""")"),"") | O35: =IFERROR(__xludf.DUMMYFUNCTION("IF(A35>0,IFERROR(MAX(FILTER('Барабан'!AJ:AJ,'Барабан'!V:V=A35)),""–""),"""")"),"")
A36: ='Справочник'!E31 | B36: =IF(A36>0,SUMIF('Барабан'!K:K,A36,'Барабан'!I:I),"") | C36: =IF(A36>0,SUMIF('Барабан'!V:V,A36,'Барабан'!T:T),"") | D36: =IF(A36>0,SUMIF('Барабан'!K:K,A36,'Барабан'!AG:AG)+SUMIF('Барабан'!V:V,A36,'Барабан'!AG:AG),"") | E36: =IF(A36>0,ROUND(B36-C36,0),"") | F36: {=IFERROR(IF(E36=0,0,INDEX('Справочник'!G:G,MATCH(A36,'Справочник'!F:F,0))))} | G36: =IF(A36>0,SUMIF('Барабан'!K:K,A36,'Барабан'!P:P),"") | H36: =IF(A36>0,SUMIF('Барабан'!V:V,A36,'Барабан'!AA:AA),"") | I36: =IF(A36>0,H36+F36-G36-D36,"") | J36: =IFERROR(IF(A36>0,I36/G36,""),"–") | K36: =IF(A36>0,COUNTIF('Барабан'!K:K,A36),"") | L36: =IF(A36>0,COUNTIF('Барабан'!V:V,A36),"") | M36: =IF(A36>0,IFERROR(O36-N36,TODAY()-N36),"") | N36: =IFERROR(__xludf.DUMMYFUNCTION("IF(A36>0,MIN(FILTER('Барабан'!AJ:AJ,'Барабан'!K:K=A36)),"""")"),"") | O36: =IFERROR(__xludf.DUMMYFUNCTION("IF(A36>0,IFERROR(MAX(FILTER('Барабан'!AJ:AJ,'Барабан'!V:V=A36)),""–""),"""")"),"")
A37: ='Справочник'!E32 | B37: =IF(A37>0,SUMIF('Барабан'!K:K,A37,'Барабан'!I:I),"") | C37: =IF(A37>0,SUMIF('Барабан'!V:V,A37,'Барабан'!T:T),"") | D37: =IF(A37>0,SUMIF('Барабан'!K:K,A37,'Барабан'!AG:AG)+SUMIF('Барабан'!V:V,A37,'Барабан'!AG:AG),"") | E37: =IF(A37>0,ROUND(B37-C37,0),"") | F37: {=IFERROR(IF(E37=0,0,INDEX('Справочник'!G:G,MATCH(A37,'Справочник'!F:F,0))))} | G37: =IF(A37>0,SUMIF('Барабан'!K:K,A37,'Барабан'!P:P),"") | H37: =IF(A37>0,SUMIF('Барабан'!V:V,A37,'Барабан'!AA:AA),"") | I37: =IF(A37>0,H37+F37-G37-D37,"") | J37: =IFERROR(IF(A37>0,I37/G37,""),"–") | K37: =IF(A37>0,COUNTIF('Барабан'!K:K,A37),"") | L37: =IF(A37>0,COUNTIF('Барабан'!V:V,A37),"") | M37: =IF(A37>0,IFERROR(O37-N37,TODAY()-N37),"") | N37: =IFERROR(__xludf.DUMMYFUNCTION("IF(A37>0,MIN(FILTER('Барабан'!AJ:AJ,'Барабан'!K:K=A37)),"""")"),"") | O37: =IFERROR(__xludf.DUMMYFUNCTION("IF(A37>0,IFERROR(MAX(FILTER('Барабан'!AJ:AJ,'Барабан'!V:V=A37)),""–""),"""")"),"")
A38: ='Справочник'!E33 | B38: =IF(A38>0,SUMIF('Барабан'!K:K,A38,'Барабан'!I:I),"") | C38: =IF(A38>0,SUMIF('Барабан'!V:V,A38,'Барабан'!T:T),"") | D38: =IF(A38>0,SUMIF('Барабан'!K:K,A38,'Барабан'!AG:AG)+SUMIF('Барабан'!V:V,A38,'Барабан'!AG:AG),"") | E38: =IF(A38>0,ROUND(B38-C38,0),"") | F38: {=IFERROR(IF(E38=0,0,INDEX('Справочник'!G:G,MATCH(A38,'Справочник'!F:F,0))))} | G38: =IF(A38>0,SUMIF('Барабан'!K:K,A38,'Барабан'!P:P),"") | H38: =IF(A38>0,SUMIF('Барабан'!V:V,A38,'Барабан'!AA:AA),"") | I38: =IF(A38>0,H38+F38-G38-D38,"") | J38: =IFERROR(IF(A38>0,I38/G38,""),"–") | K38: =IF(A38>0,COUNTIF('Барабан'!K:K,A38),"") | L38: =IF(A38>0,COUNTIF('Барабан'!V:V,A38),"") | M38: =IF(A38>0,IFERROR(O38-N38,TODAY()-N38),"") | N38: =IFERROR(__xludf.DUMMYFUNCTION("IF(A38>0,MIN(FILTER('Барабан'!AJ:AJ,'Барабан'!K:K=A38)),"""")"),"") | O38: =IFERROR(__xludf.DUMMYFUNCTION("IF(A38>0,IFERROR(MAX(FILTER('Барабан'!AJ:AJ,'Барабан'!V:V=A38)),""–""),"""")"),"")
A39: ='Справочник'!E34 | B39: =IF(A39>0,SUMIF('Барабан'!K:K,A39,'Барабан'!I:I),"") | C39: =IF(A39>0,SUMIF('Барабан'!V:V,A39,'Барабан'!T:T),"") | D39: =IF(A39>0,SUMIF('Барабан'!K:K,A39,'Барабан'!AG:AG)+SUMIF('Барабан'!V:V,A39,'Барабан'!AG:AG),"") | E39: =IF(A39>0,ROUND(B39-C39,0),"") | F39: {=IFERROR(IF(E39=0,0,INDEX('Справочник'!G:G,MATCH(A39,'Справочник'!F:F,0))))} | G39: =IF(A39>0,SUMIF('Барабан'!K:K,A39,'Барабан'!P:P),"") | H39: =IF(A39>0,SUMIF('Барабан'!V:V,A39,'Барабан'!AA:AA),"") | I39: =IF(A39>0,H39+F39-G39-D39,"") | J39: =IFERROR(IF(A39>0,I39/G39,""),"–") | K39: =IF(A39>0,COUNTIF('Барабан'!K:K,A39),"") | L39: =IF(A39>0,COUNTIF('Барабан'!V:V,A39),"") | M39: =IF(A39>0,IFERROR(O39-N39,TODAY()-N39),"") | N39: =IFERROR(__xludf.DUMMYFUNCTION("IF(A39>0,MIN(FILTER('Барабан'!AJ:AJ,'Барабан'!K:K=A39)),"""")"),"") | O39: =IFERROR(__xludf.DUMMYFUNCTION("IF(A39>0,IFERROR(MAX(FILTER('Барабан'!AJ:AJ,'Барабан'!V:V=A39)),""–""),"""")"),"")
A40: ='Справочник'!E35 | B40: =IF(A40>0,SUMIF('Барабан'!K:K,A40,'Барабан'!I:I),"") | C40: =IF(A40>0,SUMIF('Барабан'!V:V,A40,'Барабан'!T:T),"") | D40: =IF(A40>0,SUMIF('Барабан'!K:K,A40,'Барабан'!AG:AG)+SUMIF('Барабан'!V:V,A40,'Барабан'!AG:AG),"") | E40: =IF(A40>0,ROUND(B40-C40,0),"") | F40: {=IFERROR(IF(E40=0,0,INDEX('Справочник'!G:G,MATCH(A40,'Справочник'!F:F,0))))} | G40: =IF(A40>0,SUMIF('Барабан'!K:K,A40,'Барабан'!P:P),"") | H40: =IF(A40>0,SUMIF('Барабан'!V:V,A40,'Барабан'!AA:AA),"") | I40: =IF(A40>0,H40+F40-G40-D40,"") | J40: =IFERROR(IF(A40>0,I40/G40,""),"–") | K40: =IF(A40>0,COUNTIF('Барабан'!K:K,A40),"") | L40: =IF(A40>0,COUNTIF('Барабан'!V:V,A40),"") | M40: =IF(A40>0,IFERROR(O40-N40,TODAY()-N40),"") | N40: =IFERROR(__xludf.DUMMYFUNCTION("IF(A40>0,MIN(FILTER('Барабан'!AJ:AJ,'Барабан'!K:K=A40)),"""")"),"") | O40: =IFERROR(__xludf.DUMMYFUNCTION("IF(A40>0,IFERROR(MAX(FILTER('Барабан'!AJ:AJ,'Барабан'!V:V=A40)),""–""),"""")"),"")
A41: ='Справочник'!E36 | B41: =IF(A41>0,SUMIF('Барабан'!K:K,A41,'Барабан'!I:I),"") | C41: =IF(A41>0,SUMIF('Барабан'!V:V,A41,'Барабан'!T:T),"") | D41: =IF(A41>0,SUMIF('Барабан'!K:K,A41,'Барабан'!AG:AG)+SUMIF('Барабан'!V:V,A41,'Барабан'!AG:AG),"") | E41: =IF(A41>0,ROUND(B41-C41,0),"") | F41: {=IFERROR(IF(E41=0,0,INDEX('Справочник'!G:G,MATCH(A41,'Справочник'!F:F,0))))} | G41: =IF(A41>0,SUMIF('Барабан'!K:K,A41,'Барабан'!P:P),"") | H41: =IF(A41>0,SUMIF('Барабан'!V:V,A41,'Барабан'!AA:AA),"") | I41: =IF(A41>0,H41+F41-G41-D41,"") | J41: =IFERROR(IF(A41>0,I41/G41,""),"–") | K41: =IF(A41>0,COUNTIF('Барабан'!K:K,A41),"") | L41: =IF(A41>0,COUNTIF('Барабан'!V:V,A41),"") | M41: =IF(A41>0,IFERROR(O41-N41,TODAY()-N41),"") | N41: =IFERROR(__xludf.DUMMYFUNCTION("IF(A41>0,MIN(FILTER('Барабан'!AJ:AJ,'Барабан'!K:K=A41)),"""")"),"") | O41: =IFERROR(__xludf.DUMMYFUNCTION("IF(A41>0,IFERROR(MAX(FILTER('Барабан'!AJ:AJ,'Барабан'!V:V=A41)),""–""),"""")"),"")
A42: ='Справочник'!E37 | B42: =IF(A42>0,SUMIF('Барабан'!K:K,A42,'Барабан'!I:I),"") | C42: =IF(A42>0,SUMIF('Барабан'!V:V,A42,'Барабан'!T:T),"") | D42: =IF(A42>0,SUMIF('Барабан'!K:K,A42,'Барабан'!AG:AG)+SUMIF('Барабан'!V:V,A42,'Барабан'!AG:AG),"") | E42: =IF(A42>0,ROUND(B42-C42,0),"") | F42: {=IFERROR(IF(E42=0,0,INDEX('Справочник'!G:G,MATCH(A42,'Справочник'!F:F,0))))} | G42: =IF(A42>0,SUMIF('Барабан'!K:K,A42,'Барабан'!P:P),"") | H42: =IF(A42>0,SUMIF('Барабан'!V:V,A42,'Барабан'!AA:AA),"") | I42: =IF(A42>0,H42+F42-G42-D42,"") | J42: =IFERROR(IF(A42>0,I42/G42,""),"–") | K42: =IF(A42>0,COUNTIF('Барабан'!K:K,A42),"") | L42: =IF(A42>0,COUNTIF('Барабан'!V:V,A42),"") | M42: =IF(A42>0,IFERROR(O42-N42,TODAY()-N42),"") | N42: =IFERROR(__xludf.DUMMYFUNCTION("IF(A42>0,MIN(FILTER('Барабан'!AJ:AJ,'Барабан'!K:K=A42)),"""")"),"") | O42: =IFERROR(__xludf.DUMMYFUNCTION("IF(A42>0,IFERROR(MAX(FILTER('Барабан'!AJ:AJ,'Барабан'!V:V=A42)),""–""),"""")"),"")
...

Sheet Справочник
A1: Тикеры | D1: Исключить | E1: Уникальные тикеры | F1: Еще держит | G1: Текущий P&L | I1: ='Исходник'!T1 -> Tx Hash | J1: Timestamp | K1: Timestamp (х) | L1: Проверка даты | O1: Кошелек
A2: =IFERROR(__xludf.DUMMYFUNCTION("FILTER('Барабан'!K2:K1575,'Барабан'!D2:D1575=""trade"")"),"#N/A") -> #N/A | B2: =IF(A2>0,IF(ISNA(MATCH(A2,$D$2:$D$55,0)),1,0),"") -> #N/A | D2: ETH | E2: =IFERROR(__xludf.DUMMYFUNCTION("unique(FILTER(A2:A1575,B2:B1575=1))"),"#N/A") -> #N/A | F2: =IFERROR(__xludf.DUMMYFUNCTION("FILTER('Анализ'!A7:A1005,'Анализ'!E7:E1005<>0)"),"") | I2: =#REF! -> #REF! | J2: {=IFERROR(INDEX('Исходник'!$1:$626,MATCH($I2,'Исходник'!$T:$T,0),MATCH(J$1,'Исходник'!$1:$1,0)))} | K2: =IF(I2>0, VALUE(LEFT(J2,10)),"") -> #REF! | L2: =IF(I2>0,IF(TODAY()-K2<'Анализ'!$D$4+1,1,0),"") -> #REF!
B3: =IF(A3>0,IF(ISNA(MATCH(A3,$D$2:$D$55,0)),1,0),"") | D3: BNB | G3: 10630 | I3: =#REF! -> #REF! | J3: {=IFERROR(INDEX('Исходник'!$1:$626,MATCH($I3,'Исходник'!$T:$T,0),MATCH(J$1,'Исходник'!$1:$1,0)))} | K3: =IF(I3>0, VALUE(LEFT(J3,10)),"") -> #REF! | L3: =IF(I3>0,IF(TODAY()-K3<'Анализ'!$D$4+1,1,0),"") -> #REF!
B4: =IF(A4>0,IF(ISNA(MATCH(A4,$D$2:$D$55,0)),1,0),"") | D4: BUSD | G4: 4123 | I4: =#REF! -> #REF! | J4: {=IFERROR(INDEX('Исходник'!$1:$626,MATCH($I4,'Исходник'!$T:$T,0),MATCH(J$1,'Исходник'!$1:$1,0)))} | K4: =IF(I4>0, VALUE(LEFT(J4,10)),"") -> #REF! | L4: =IF(I4>0,IF(TODAY()-K4<'Анализ'!$D$4+1,1,0),"") -> #REF! | O4: FALSE | P4: Кошелек заработал больше $8к за 30 дней ?
B5: =IF(A5>0,IF(ISNA(MATCH(A5,$D$2:$D$55,0)),1,0),"") | D5: USDC | I5: =#REF! -> #REF! | J5: {=IFERROR(INDEX('Исходник'!$1:$626,MATCH($I5,'Исходник'!$T:$T,0),MATCH(J$1,'Исходник'!$1:$1,0)))} | K5: =IF(I5>0, VALUE(LEFT(J5,10)),"") -> #REF! | L5: =IF(I5>0,IF(TODAY()-K5<'Анализ'!$D$4+1,1,0),"") -> #REF! | O5: FALSE | P5: Винрейт больше 45% за 30 дней?
B6: =IF(A6>0,IF(ISNA(MATCH(A6,$D$2:$D$55,0)),1,0),"") | D6: USDT | I6: =#REF! -> #REF! | J6: {=IFERROR(INDEX('Исходник'!$1:$626,MATCH($I6,'Исходник'!$T:$T,0),MATCH(J$1,'Исходник'!$1:$1,0)))} | K6: =IF(I6>0, VALUE(LEFT(J6,10)),"") -> #REF! | L6: =IF(I6>0,IF(TODAY()-K6<'Анализ'!$D$4+1,1,0),"") -> #REF! | O6: FALSE | P6: Средняя прибыль в сделке больше 10% за 30 дней
B7: =IF(A7>0,IF(ISNA(MATCH(A7,$D$2:$D$55,0)),1,0),"") | D7: WETH | I7: =#REF! -> #REF! | J7: {=IFERROR(INDEX('Исходник'!$1:$626,MATCH($I7,'Исходник'!$T:$T,0),MATCH(J$1,'Исходник'!$1:$1,0)))} | K7: =IF(I7>0, VALUE(LEFT(J7,10)),"") -> #REF! | L7: =IF(I7>0,IF(TODAY()-K7<'Анализ'!$D$4+1,1,0),"") -> #REF! | O7: FALSE | P7: Проторговано больше 5 монет за 30 дней
B8: =IF(A8>0,IF(ISNA(MATCH(A8,$D$2:$D$55,0)),1,0),"") | D8: BITCOIN | I8: =#REF! -> #REF! | J8: {=IFERROR(INDEX('Исходник'!$1:$626,MATCH($I8,'Исходник'!$T:$T,0),MATCH(J$1,'Исходник'!$1:$1,0)))} | K8: =IF(I8>0, VALUE(LEFT(J8,10)),"") -> #REF! | L8: =IF(I8>0,IF(TODAY()-K8<'Анализ'!$D$4+1,1,0),"") -> #REF! | O8: FALSE | P8: Деньги есть на балансе?
B9: =IF(A9>0,IF(ISNA(MATCH(A9,$D$2:$D$55,0)),1,0),"") | D9: USDC.E | I9: =#REF! -> #REF! | J9: {=IFERROR(INDEX('Исходник'!$1:$626,MATCH($I9,'Исходник'!$T:$T,0),MATCH(J$1,'Исходник'!$1:$1,0)))} | K9: =IF(I9>0, VALUE(LEFT(J9,10)),"") -> #REF! | L9: =IF(I9>0,IF(TODAY()-K9<'Анализ'!$D$4+1,1,0),"") -> #REF! | O9: FALSE | P9: Кошелек начал торговать/создан более недели назад?
B10: =IF(A10>0,IF(ISNA(MATCH(A10,$D$2:$D$55,0)),1,0),"") | I10: =#REF! -> #REF! | J10: {=IFERROR(INDEX('Исходник'!$1:$626,MATCH($I10,'Исходник'!$T:$T,0),MATCH(J$1,'Исходник'!$1:$1,0)))} | K10: =IF(I10>0, VALUE(LEFT(J10,10)),"") -> #REF! | L10: =IF(I10>0,IF(TODAY()-K10<'Анализ'!$D$4+1,1,0),"") -> #REF! | O10: FALSE | P10: Кошелек в плюсе за последнюю неделю?
B11: =IF(A11>0,IF(ISNA(MATCH(A11,$D$2:$D$55,0)),1,0),"") | I11: =#REF! -> #REF! | J11: {=IFERROR(INDEX('Исходник'!$1:$626,MATCH($I11,'Исходник'!$T:$T,0),MATCH(J$1,'Исходник'!$1:$1,0)))} | K11: =IF(I11>0, VALUE(LEFT(J11,10)),"") -> #REF! | L11: =IF(I11>0,IF(TODAY()-K11<'Анализ'!$D$4+1,1,0),"") -> #REF! | O11: FALSE | P11: Кошелек в основном торгует токенами с ликвидностью выше $15к?
B12: =IF(A12>0,IF(ISNA(MATCH(A12,$D$2:$D$55,0)),1,0),"") | I12: =#REF! -> #REF! | J12: {=IFERROR(INDEX('Исходник'!$1:$626,MATCH($I12,'Исходник'!$T:$T,0),MATCH(J$1,'Исходник'!$1:$1,0)))} | K12: =IF(I12>0, VALUE(LEFT(J12,10)),"") -> #REF! | L12: =IF(I12>0,IF(TODAY()-K12<'Анализ'!$D$4+1,1,0),"") -> #REF! | O12: FALSE | P12: У кошелька меньше 15% скам токенов?
B13: =IF(A13>0,IF(ISNA(MATCH(A13,$D$2:$D$55,0)),1,0),"") | I13: =#REF! -> #REF! | J13: {=IFERROR(INDEX('Исходник'!$1:$626,MATCH($I13,'Исходник'!$T:$T,0),MATCH(J$1,'Исходник'!$1:$1,0)))} | K13: =IF(I13>0, VALUE(LEFT(J13,10)),"") -> #REF! | L13: =IF(I13>0,IF(TODAY()-K13<'Анализ'!$D$4+1,1,0),"") -> #REF! | O13: FALSE | P13: Вы бы успевали потвторять и зарабатывать вместе с ним?
B14: =IF(A14>0,IF(ISNA(MATCH(A14,$D$2:$D$55,0)),1,0),"") | I14: =#REF! -> #REF! | J14: {=IFERROR(INDEX('Исходник'!$1:$626,MATCH($I14,'Исходник'!$T:$T,0),MATCH(J$1,'Исходник'!$1:$1,0)))} | K14: =IF(I14>0, VALUE(LEFT(J14,10)),"") -> #REF! | L14: =IF(I14>0,IF(TODAY()-K14<'Анализ'!$D$4+1,1,0),"") -> #REF! | O14: =COUNTIF(O4:O13,TRUE()) -> 0 | P14: =IF(O14>8,"Кошелек подходит для слежения",IF(O14>6,"Кошелек можно добавить в базу, ждём улучшения показателей","Кошелек не подходит по параметрам")) -> Кошелек не подходит по параметрам
B15: =IF(A15>0,IF(ISNA(MATCH(A15,$D$2:$D$55,0)),1,0),"") | I15: =#REF! -> #REF! | J15: {=IFERROR(INDEX('Исходник'!$1:$626,MATCH($I15,'Исходник'!$T:$T,0),MATCH(J$1,'Исходник'!$1:$1,0)))} | K15: =IF(I15>0, VALUE(LEFT(J15,10)),"") -> #REF! | L15: =IF(I15>0,IF(TODAY()-K15<'Анализ'!$D$4+1,1,0),"") -> #REF!
B16: =IF(A16>0,IF(ISNA(MATCH(A16,$D$2:$D$55,0)),1,0),"") | I16: =#REF! -> #REF! | J16: {=IFERROR(INDEX('Исходник'!$1:$626,MATCH($I16,'Исходник'!$T:$T,0),MATCH(J$1,'Исходник'!$1:$1,0)))} | K16: =IF(I16>0, VALUE(LEFT(J16,10)),"") -> #REF! | L16: =IF(I16>0,IF(TODAY()-K16<'Анализ'!$D$4+1,1,0),"") -> #REF!
B17: =IF(A17>0,IF(ISNA(MATCH(A17,$D$2:$D$55,0)),1,0),"") | I17: =#REF! -> #REF! | J17: {=IFERROR(INDEX('Исходник'!$1:$626,MATCH($I17,'Исходник'!$T:$T,0),MATCH(J$1,'Исходник'!$1:$1,0)))} | K17: =IF(I17>0, VALUE(LEFT(J17,10)),"") -> #REF! | L17: =IF(I17>0,IF(TODAY()-K17<'Анализ'!$D$4+1,1,0),"") -> #REF!
B18: =IF(A18>0,IF(ISNA(MATCH(A18,$D$2:$D$55,0)),1,0),"") | I18: =#REF! -> #REF! | J18: {=IFERROR(INDEX('Исходник'!$1:$626,MATCH($I18,'Исходник'!$T:$T,0),MATCH(J$1,'Исходник'!$1:$1,0)))} | K18: =IF(I18>0, VALUE(LEFT(J18,10)),"") -> #REF! | L18: =IF(I18>0,IF(TODAY()-K18<'Анализ'!$D$4+1,1,0),"") -> #REF!
B19: =IF(A19>0,IF(ISNA(MATCH(A19,$D$2:$D$55,0)),1,0),"") | I19: =#REF! -> #REF! | J19: {=IFERROR(INDEX('Исходник'!$1:$626,MATCH($I19,'Исходник'!$T:$T,0),MATCH(J$1,'Исходник'!$1:$1,0)))} | K19: =IF(I19>0, VALUE(LEFT(J19,10)),"") -> #REF! | L19: =IF(I19>0,IF(TODAY()-K19<'Анализ'!$D$4+1,1,0),"") -> #REF!
B20: =IF(A20>0,IF(ISNA(MATCH(A20,$D$2:$D$55,0)),1,0),"") | I20: =#REF! -> #REF! | J20: {=IFERROR(INDEX('Исходник'!$1:$626,MATCH($I20,'Исходник'!$T:$T,0),MATCH(J$1,'Исходник'!$1:$1,0)))} | K20: =IF(I20>0, VALUE(LEFT(J20,10)),"") -> #REF! | L20: =IF(I20>0,IF(TODAY()-K20<'Анализ'!$D$4+1,1,0),"") -> #REF!
B21: =IF(A21>0,IF(ISNA(MATCH(A21,$D$2:$D$55,0)),1,0),"") | I21: =#REF! -> #REF! | J21: {=IFERROR(INDEX('Исходник'!$1:$626,MATCH($I21,'Исходник'!$T:$T,0),MATCH(J$1,'Исходник'!$1:$1,0)))} | K21: =IF(I21>0, VALUE(LEFT(J21,10)),"") -> #REF! | L21: =IF(I21>0,IF(TODAY()-K21<'Анализ'!$D$4+1,1,0),"") -> #REF!
B22: =IF(A22>0,IF(ISNA(MATCH(A22,$D$2:$D$55,0)),1,0),"") | I22: =#REF! -> #REF! | J22: {=IFERROR(INDEX('Исходник'!$1:$626,MATCH($I22,'Исходник'!$T:$T,0),MATCH(J$1,'Исходник'!$1:$1,0)))} | K22: =IF(I22>0, VALUE(LEFT(J22,10)),"") -> #REF! | L22: =IF(I22>0,IF(TODAY()-K22<'Анализ'!$D$4+1,1,0),"") -> #REF!
B23: =IF(A23>0,IF(ISNA(MATCH(A23,$D$2:$D$55,0)),1,0),"") | I23: =#REF! -> #REF! | J23: {=IFERROR(INDEX('Исходник'!$1:$626,MATCH($I23,'Исходник'!$T:$T,0),MATCH(J$1,'Исходник'!$1:$1,0)))} | K23: =IF(I23>0, VALUE(LEFT(J23,10)),"") -> #REF! | L23: =IF(I23>0,IF(TODAY()-K23<'Анализ'!$D$4+1,1,0),"") -> #REF!
B24: =IF(A24>0,IF(ISNA(MATCH(A24,$D$2:$D$55,0)),1,0),"") | I24: =#REF! -> #REF! | J24: {=IFERROR(INDEX('Исходник'!$1:$626,MATCH($I24,'Исходник'!$T:$T,0),MATCH(J$1,'Исходник'!$1:$1,0)))} | K24: =IF(I24>0, VALUE(LEFT(J24,10)),"") -> #REF! | L24: =IF(I24>0,IF(TODAY()-K24<'Анализ'!$D$4+1,1,0),"") -> #REF!
B25: =IF(A25>0,IF(ISNA(MATCH(A25,$D$2:$D$55,0)),1,0),"") | I25: =#REF! -> #REF! | J25: {=IFERROR(INDEX('Исходник'!$1:$626,MATCH($I25,'Исходник'!$T:$T,0),MATCH(J$1,'Исходник'!$1:$1,0)))} | K25: =IF(I25>0, VALUE(LEFT(J25,10)),"") -> #REF! | L25: =IF(I25>0,IF(TODAY()-K25<'Анализ'!$D$4+1,1,0),"") -> #REF!
B26: =IF(A26>0,IF(ISNA(MATCH(A26,$D$2:$D$55,0)),1,0),"") | I26: =#REF! -> #REF! | J26: {=IFERROR(INDEX('Исходник'!$1:$626,MATCH($I26,'Исходник'!$T:$T,0),MATCH(J$1,'Исходник'!$1:$1,0)))} | K26: =IF(I26>0, VALUE(LEFT(J26,10)),"") -> #REF! | L26: =IF(I26>0,IF(TODAY()-K26<'Анализ'!$D$4+1,1,0),"") -> #REF!
... B375: =IF(A375>0,IF(ISNA(MATCH(A375,$D$2:$D$55,0)),1,0),"") | I375: =#REF! -> #REF! | J375: {=IFERROR(INDEX('Исходник'!$1:$626,MATCH($I375,'Исходник'!$T:$T,0),MATCH(J$1,'Исходник'!$1:$1,0)))} | K375: =IF(I375>0, VALUE(LEFT(J375,10)),"") -> #REF! | L375: =IF(I375>0,IF(TODAY()-K375<'Анализ'!$D$4+1,1,0),"") -> #REF!
B376: =IF(A376>0,IF(ISNA(MATCH(A376,$D$2:$D$55,0)),1,0),"") | I376: ='Исходник'!T2 | J376: {=IFERROR(INDEX('Исходник'!$1:$626,MATCH($I376,'Исходник'!$T:$T,0),MATCH(J$1,'Исходник'!$1:$1,0)))} | K376: =IF(I376>0, VALUE(LEFT(J376,10)),"") | L376: =IF(I376>0,IF(TODAY()-K376<'Анализ'!$D$4+1,1,0),"")
B377: =IF(A377>0,IF(ISNA(MATCH(A377,$D$2:$D$55,0)),1,0),"") | I377: ='Исходник'!T3 | J377: {=IFERROR(INDEX('Исходник'!$1:$626,MATCH($I377,'Исходник'!$T:$T,0),MATCH(J$1,'Исходник'!$1:$1,0)))} | K377: =IF(I377>0, VALUE(LEFT(J377,10)),"") | L377: =IF(I377>0,IF(TODAY()-K377<'Анализ'!$D$4+1,1,0),"")
B378: =IF(A378>0,IF(ISNA(MATCH(A378,$D$2:$D$55,0)),1,0),"") | I378: ='Исходник'!T4 | J378: {=IFERROR(INDEX('Исходник'!$1:$626,MATCH($I378,'Исходник'!$T:$T,0),MATCH(J$1,'Исходник'!$1:$1,0)))} | K378: =IF(I378>0, VALUE(LEFT(J378,10)),"") | L378: =IF(I378>0,IF(TODAY()-K378<'Анализ'!$D$4+1,1,0),"")
B379: =IF(A379>0,IF(ISNA(MATCH(A379,$D$2:$D$55,0)),1,0),"") | I379: ='Исходник'!T5 | J379: {=IFERROR(INDEX('Исходник'!$1:$626,MATCH($I379,'Исходник'!$T:$T,0),MATCH(J$1,'Исходник'!$1:$1,0)))} | K379: =IF(I379>0, VALUE(LEFT(J379,10)),"") | L379: =IF(I379>0,IF(TODAY()-K379<'Анализ'!$D$4+1,1,0),"")
B380: =IF(A380>0,IF(ISNA(MATCH(A380,$D$2:$D$55,0)),1,0),"") | I380: ='Исходник'!T6 | J380: {=IFERROR(INDEX('Исходник'!$1:$626,MATCH($I380,'Исходник'!$T:$T,0),MATCH(J$1,'Исходник'!$1:$1,0)))} | K380: =IF(I380>0, VALUE(LEFT(J380,10)),"") | L380: =IF(I380>0,IF(TODAY()-K380<'Анализ'!$D$4+1,1,0),"")
B381: =IF(A381>0,IF(ISNA(MATCH(A381,$D$2:$D$55,0)),1,0),"") | I381: ='Исходник'!T7 | J381: {=IFERROR(INDEX('Исходник'!$1:$626,MATCH($I381,'Исходник'!$T:$T,0),MATCH(J$1,'Исходник'!$1:$1,0)))} | K381: =IF(I381>0, VALUE(LEFT(J381,10)),"") | L381: =IF(I381>0,IF(TODAY()-K381<'Анализ'!$D$4+1,1,0),"")
B382: =IF(A382>0,IF(ISNA(MATCH(A382,$D$2:$D$55,0)),1,0),"") | I382: ='Исходник'!T8 | J382: {=IFERROR(INDEX('Исходник'!$1:$626,MATCH($I382,'Исходник'!$T:$T,0),MATCH(J$1,'Исходник'!$1:$1,0)))} | K382: =IF(I382>0, VALUE(LEFT(J382,10)),"") | L382: =IF(I382>0,IF(TODAY()-K382<'Анализ'!$D$4+1,1,0),"")
B383: =IF(A383>0,IF(ISNA(MATCH(A383,$D$2:$D$55,0)),1,0),"") | I383: ='Исходник'!T9 | J383: {=IFERROR(INDEX('Исходник'!$1:$626,MATCH($I383,'Исходник'!$T:$T,0),MATCH(J$1,'Исходник'!$1:$1,0)))} | K383: =IF(I383>0, VALUE(LEFT(J383,10)),"") | L383: =IF(I383>0,IF(TODAY()-K383<'Анализ'!$D$4+1,1,0),"")
B384: =IF(A384>0,IF(ISNA(MATCH(A384,$D$2:$D$55,0)),1,0),"") | I384: ='Исходник'!T10 | J384: {=IFERROR(INDEX('Исходник'!$1:$626,MATCH($I384,'Исходник'!$T:$T,0),MATCH(J$1,'Исходник'!$1:$1,0)))} | K384: =IF(I384>0, VALUE(LEFT(J384,10)),"") | L384: =IF(I384>0,IF(TODAY()-K384<'Анализ'!$D$4+1,1,0),"")
B385: =IF(A385>0,IF(ISNA(MATCH(A385,$D$2:$D$55,0)),1,0),"") | I385: ='Исходник'!T11 | J385: {=IFERROR(INDEX('Исходник'!$1:$626,MATCH($I385,'Исходник'!$T:$T,0),MATCH(J$1,'Исходник'!$1:$1,0)))} | K385: =IF(I385>0, VALUE(LEFT(J385,10)),"") | L385: =IF(I385>0,IF(TODAY()-K385<'Анализ'!$D$4+1,1,0),"")
B386: =IF(A386>0,IF(ISNA(MATCH(A386,$D$2:$D$55,0)),1,0),"") | I386: ='Исходник'!T12 | J386: {=IFERROR(INDEX('Исходник'!$1:$626,MATCH($I386,'Исходник'!$T:$T,0),MATCH(J$1,'Исходник'!$1:$1,0)))} | K386: =IF(I386>0, VALUE(LEFT(J386,10)),"") | L386: =IF(I386>0,IF(TODAY()-K386<'Анализ'!$D$4+1,1,0),"")
B387: =IF(A387>0,IF(ISNA(MATCH(A387,$D$2:$D$55,0)),1,0),"") | I387: ='Исходник'!T13 | J387: {=IFERROR(INDEX('Исходник'!$1:$626,MATCH($I387,'Исходник'!$T:$T,0),MATCH(J$1,'Исходник'!$1:$1,0)))} | K387: =IF(I387>0, VALUE(LEFT(J387,10)),"") | L387: =IF(I387>0,IF(TODAY()-K387<'Анализ'!$D$4+1,1,0),"")
... B1000: =IF(A1000>0,IF(ISNA(MATCH(A1000,$D$2:$D$55,0)),1,0),"") | I1000: ='Исходник'!T626 | J1000: {=IFERROR(INDEX('Исходник'!$1:$626,MATCH($I1000,'Исходник'!$T:$T,0),MATCH(J$1,'Исходник'!$1:$1,0)))} | K1000: =IF(I1000>0, VALUE(LEFT(J1000,10)),"") | L1000: =IF(I1000>0,IF(TODAY()-K1000<'Анализ'!$D$4+1,1,0),"")
...

Sheet Барабан
A1: ='Исходник'!T1 -> Tx Hash | B1: Date | C1: Time | D1: Transaction Type | E1: Status | F1: Chain | G1: Buy Amount | H1: Buy Amount (х1) | I1: Buy Amount (х) | J1: Buy Currency | K1: Buy Currency (х) | L1: Buy Currency Address | M1: Больший транзакции | N1: Buy Fiat Amount | O1: Buy Fiat Amount (х1) | P1: Buy Fiat Amount (х) | Q1: Buy Fiat Currency | R1: Sell Amount | S1: Sell Amount (х1) | T1: Sell Amount (х) | U1: Sell Currency | V1: Sell Currency (х) | W1: Sell Currency Address | X1: Больший транзакции (sell) | Y1: Sell Fiat Amount | Z1: Sell Fiat Amount (х1) | AA1: Sell Fiat Amount (х) | AB1: Sell Fiat Currency | AC1: Fee Amount | AD1: Fee Amount (х) | AE1: Fee Currency | AF1: Fee Fiat Amount | AG1: Fee Fiat Amount (х) | AH1: Fee Fiat Currency | AI1: Timestamp | AJ1: Timestamp (х)
A2: =IFERROR(__xludf.DUMMYFUNCTION("FILTER('Справочник'!I2:I1000,'Справочник'!L2:L1000=1)"),"#N/A") -> #N/A | B2: {=IFERROR(INDEX('Исходник'!$1:$626,MATCH($A2,'Исходник'!$T:$T,0),MATCH(B$1,'Исходник'!$1:$1,0)))} | C2: {=IFERROR(INDEX('Исходник'!$1:$626,MATCH($A2,'Исходник'!$T:$T,0),MATCH(C$1,'Исходник'!$1:$1,0)))} | D2: {=IFERROR(INDEX('Исходник'!$1:$626,MATCH($A2,'Исходник'!$T:$T,0),MATCH(D$1,'Исходник'!$1:$1,0)))} | E2: {=IFERROR(INDEX('Исходник'!$1:$626,MATCH($A2,'Исходник'!$T:$T,0),MATCH(E$1,'Исходник'!$1:$1,0)))} | F2: {=IFERROR(INDEX('Исходник'!$1:$626,MATCH($A2,'Исходник'!$T:$T,0),MATCH(F$1,'Исходник'!$1:$1,0)))} | G2: {=IFERROR(INDEX('Исходник'!$1:$626,MATCH($A2,'Исходник'!$T:$T,0),MATCH(G$1,'Исходник'!$1:$1,0)))} | H2: =IF(IFERROR(SEARCH(" ",G2))>0,SUM(IFERROR(VALUE(REPLACE(LEFT(G2,SEARCH(" ",G2)-1),SEARCH(".",LEFT(G2,SEARCH(" ",G2)-1),1),1,",")),LEFT(G2,SEARCH(" ",G2)-1)),IFERROR(VALUE(REPLACE(MID(G2,SEARCH(" ",G2)+1,LEN(G2)-SEARCH(" ",G2)),SEARCH(".",MID(G2,SEARCH(" ",G2)+1,LEN(G2)-SEARCH(" ",G2)),1),1,",")),MID(G2,SEARCH(" ",G2)+1,LEN(G2)-SEARCH(" ",G2)))),0) -> 0 | I2: =IF(H2>0,H2,IFERROR(VALUE(REPLACE(G2,SEARCH(".",G2,1),1,",")),G2)) | J2: {=IFERROR(INDEX('Исходник'!$1:$626,MATCH($A2,'Исходник'!$T:$T,0),MATCH(J$1,'Исходник'!$1:$1,0)))} | K2: =IFERROR(MID(J2,1,SEARCH(" ",J2,1)-1),J2) | L2: {=IFERROR(INDEX('Исходник'!$1:$626,MATCH($A2,'Исходник'!$T:$T,0),MATCH(L$1,'Исходник'!$1:$1,0)))} | M2: =IF(LEN(L2)>90,1,0) -> 0 | N2: {=IFERROR(INDEX('Исходник'!$1:$626,MATCH($A2,'Исходник'!$T:$T,0),MATCH(N$1,'Исходник'!$1:$1,0)))} | O2: =IF(IFERROR(SEARCH(" ",N2))>0,SUM(IFERROR(VALUE(REPLACE(LEFT(N2,SEARCH(" ",N2)-1),SEARCH(".",LEFT(N2,SEARCH(" ",N2)-1),1),1,",")),LEFT(N2,SEARCH(" ",N2)-1)),IFERROR(VALUE(REPLACE(MID(N2,SEARCH(" ",N2)+1,LEN(N2)-SEARCH(" ",N2)),SEARCH(".",MID(N2,SEARCH(" ",N2)+1,LEN(N2)-SEARCH(" ",N2)),1),1,",")),MID(N2,SEARCH(" ",N2)+1,LEN(N2)-SEARCH(" ",N2)))),0) -> 0 | P2: =IF(O2>0,O2,IFERROR(VALUE(REPLACE(N2,SEARCH(".",N2,1),1,",")),N2)) | Q2: {=IFERROR(INDEX('Исходник'!$1:$626,MATCH($A2,'Исходник'!$T:$T,0),MATCH(Q$1,'Исходник'!$1:$1,0)))} | R2: {=IFERROR(INDEX('Исходник'!$1:$626,MATCH($A2,'Исходник'!$T:$T,0),MATCH(R$1,'Исходник'!$1:$1,0)))} | S2: =IF(IFERROR(SEARCH(" ",R2))>0,SUM(IFERROR(VALUE(REPLACE(LEFT(R2,SEARCH(" ",R2)-1),SEARCH(".",LEFT(R2,SEARCH(" ",R2)-1),1),1,",")),LEFT(R2,SEARCH(" ",R2)-1)),IFERROR(VALUE(REPLACE(MID(R2,SEARCH(" ",R2)+1,LEN(R2)-SEARCH(" ",R2)),SEARCH(".",MID(R2,SEARCH(" ",R2)+1,LEN(R2)-SEARCH(" ",R2)),1),1,",")),MID(R2,SEARCH(" ",R2)+1,LEN(R2)-SEARCH(" ",R2)))),0) -> 0 | T2: =IF(S2>0,S2,IFERROR(VALUE(REPLACE(R2,SEARCH(".",R2,1),1,",")),R2)) | U2: {=IFERROR(INDEX('Исходник'!$1:$626,MATCH($A2,'Исходник'!$T:$T,0),MATCH(U$1,'Исходник'!$1:$1,0)))} | V2: =IFERROR(MID(U2,1,SEARCH(" ",U2,1)-1),U2) | W2: {=IFERROR(INDEX('Исходник'!$1:$626,MATCH($A2,'Исходник'!$T:$T,0),MATCH(W$1,'Исходник'!$1:$1,0)))} | X2: =IF(LEN(W2)>90,1,0) -> 0 | Y2: {=IFERROR(INDEX('Исходник'!$1:$626,MATCH($A2,'Исходник'!$T:$T,0),MATCH(Y$1,'Исходник'!$1:$1,0)))} | Z2: =IF(IFERROR(SEARCH(" ",Y2))>0,SUM(IFERROR(VALUE(REPLACE(LEFT(Y2,SEARCH(" ",Y2)-1),SEARCH(".",LEFT(Y2,SEARCH(" ",Y2)-1),1),1,",")),LEFT(Y2,SEARCH(" ",Y2)-1)),IFERROR(VALUE(REPLACE(MID(Y2,SEARCH(" ",Y2)+1,LEN(Y2)-SEARCH(" ",Y2)),SEARCH(".",MID(Y2,SEARCH(" ",Y2)+1,LEN(Y2)-SEARCH(" ",Y2)),1),1,",")),MID(Y2,SEARCH(" ",Y2)+1,LEN(Y2)-SEARCH(" ",Y2)))),0) -> 0 | AA2: =IF(Z2>0,Z2,IFERROR(VALUE(REPLACE(Y2,SEARCH(".",Y2,1),1,",")),Y2)) | AB2: {=IFERROR(INDEX('Исходник'!$1:$626,MATCH($A2,'Исходник'!$T:$T,0),MATCH(AB$1,'Исходник'!$1:$1,0)))} | AC2: {=IFERROR(INDEX('Исходник'!$1:$626,MATCH($A2,'Исходник'!$T:$T,0),MATCH(AC$1,'Исходник'!$1:$1,0)))} | AD2: =IFERROR(VALUE(REPLACE(AC2,SEARCH(".",AC2,1),1,",")),AC2) | AE2: {=IFERROR(INDEX('Исходник'!$1:$626,MATCH($A2,'Исходник'!$T:$T,0),MATCH(AE$1,'Исходник'!$1:$1,0)))} | AF2: {=IFERROR(INDEX('Исходник'!$1:$626,MATCH($A2,'Исходник'!$T:$T,0),MATCH(AF$1,'Исходник'!$1:$1,0)))} | AG2: =IFERROR(VALUE(REPLACE(AF2,SEARCH(".",AF2,1),1,",")),AF2) | AH2: {=IFERROR(INDEX('Исходник'!$1:$626,MATCH($A2,'Исходник'!$T:$T,0),MATCH(AH$1,'Исходник'!$1:$1,0)))} | AI2: {=IFERROR(INDEX('Исходник'!$1:$626,MATCH($A2,'Исходник'!$T:$T,0),MATCH(AI$1,'Исходник'!$1:$1,0)))} | AJ2: =VALUE(LEFT(AI2,10)) -> 0
B3: {=IFERROR(INDEX('Исходник'!$1:$626,MATCH($A3,'Исходник'!$T:$T,0),MATCH(B$1,'Исходник'!$1:$1,0)))} | C3: {=IFERROR(INDEX('Исходник'!$1:$626,MATCH($A3,'Исходник'!$T:$T,0),MATCH(C$1,'Исходник'!$1:$1,0)))} | D3: {=IFERROR(INDEX('Исходник'!$1:$626,MATCH($A3,'Исходник'!$T:$T,0),MATCH(D$1,'Исходник'!$1:$1,0)))} | E3: {=IFERROR(INDEX('Исходник'!$1:$626,MATCH($A3,'Исходник'!$T:$T,0),MATCH(E$1,'Исходник'!$1:$1,0)))} | F3: {=IFERROR(INDEX('Исходник'!$1:$626,MATCH($A3,'Исходник'!$T:$T,0),MATCH(F$1,'Исходник'!$1:$1,0)))} | G3: {=IFERROR(INDEX('Исходник'!$1:$626,MATCH($A3,'Исходник'!$T:$T,0),MATCH(G$1,'Исходник'!$1:$1,0)))} | H3: =IF(IFERROR(SEARCH(" ",G3))>0,SUM(IFERROR(VALUE(REPLACE(LEFT(G3,SEARCH(" ",G3)-1),SEARCH(".",LEFT(G3,SEARCH(" ",G3)-1),1),1,",")),LEFT(G3,SEARCH(" ",G3)-1)),IFERROR(VALUE(REPLACE(MID(G3,SEARCH(" ",G3)+1,LEN(G3)-SEARCH(" ",G3)),SEARCH(".",MID(G3,SEARCH(" ",G3)+1,LEN(G3)-SEARCH(" ",G3)),1),1,",")),MID(G3,SEARCH(" ",G3)+1,LEN(G3)-SEARCH(" ",G3)))),0) -> 0 | I3: =IF(H3>0,H3,IFERROR(VALUE(REPLACE(G3,SEARCH(".",G3,1),1,",")),G3)) | J3: {=IFERROR(INDEX('Исходник'!$1:$626,MATCH($A3,'Исходник'!$T:$T,0),MATCH(J$1,'Исходник'!$1:$1,0)))} | K3: =IFERROR(MID(J3,1,SEARCH(" ",J3,1)-1),J3) | L3: {=IFERROR(INDEX('Исходник'!$1:$626,MATCH($A3,'Исходник'!$T:$T,0),MATCH(L$1,'Исходник'!$1:$1,0)))} | M3: =IF(LEN(L3)>90,1,0) -> 0 | N3: {=IFERROR(INDEX('Исходник'!$1:$626,MATCH($A3,'Исходник'!$T:$T,0),MATCH(N$1,'Исходник'!$1:$1,0)))} | O3: =IF(IFERROR(SEARCH(" ",N3))>0,SUM(IFERROR(VALUE(REPLACE(LEFT(N3,SEARCH(" ",N3)-1),SEARCH(".",LEFT(N3,SEARCH(" ",N3)-1),1),1,",")),LEFT(N3,SEARCH(" ",N3)-1)),IFERROR(VALUE(REPLACE(MID(N3,SEARCH(" ",N3)+1,LEN(N3)-SEARCH(" ",N3)),SEARCH(".",MID(N3,SEARCH(" ",N3)+1,LEN(N3)-SEARCH(" ",N3)),1),1,",")),MID(N3,SEARCH(" ",N3)+1,LEN(N3)-SEARCH(" ",N3)))),0) -> 0 | P3: =IF(O3>0,O3,IFERROR(VALUE(REPLACE(N3,SEARCH(".",N3,1),1,",")),N3)) | Q3: {=IFERROR(INDEX('Исходник'!$1:$626,MATCH($A3,'Исходник'!$T:$T,0),MATCH(Q$1,'Исходник'!$1:$1,0)))} | R3: {=IFERROR(INDEX('Исходник'!$1:$626,MATCH($A3,'Исходник'!$T:$T,0),MATCH(R$1,'Исходник'!$1:$1,0)))} | S3: =IF(IFERROR(SEARCH(" ",R3))>0,SUM(IFERROR(VALUE(REPLACE(LEFT(R3,SEARCH(" ",R3)-1),SEARCH(".",LEFT(R3,SEARCH(" ",R3)-1),1),1,",")),LEFT(R3,SEARCH(" ",R3)-1)),IFERROR(VALUE(REPLACE(MID(R3,SEARCH(" ",R3)+1,LEN(R3)-SEARCH(" ",R3)),SEARCH(".",MID(R3,SEARCH(" ",R3)+1,LEN(R3)-SEARCH(" ",R3)),1),1,",")),MID(R3,SEARCH(" ",R3)+1,LEN(R3)-SEARCH(" ",R3)))),0) -> 0 | T3: =IF(S3>0,S3,IFERROR(VALUE(REPLACE(R3,SEARCH(".",R3,1),1,",")),R3)) | U3: {=IFERROR(INDEX('Исходник'!$1:$626,MATCH($A3,'Исходник'!$T:$T,0),MATCH(U$1,'Исходник'!$1:$1,0)))} | V3: =IFERROR(MID(U3,1,SEARCH(" ",U3,1)-1),U3) | W3: {=IFERROR(INDEX('Исходник'!$1:$626,MATCH($A3,'Исходник'!$T:$T,0),MATCH(W$1,'Исходник'!$1:$1,0)))} | X3: =IF(LEN(W3)>90,1,0) -> 0 | Y3: {=IFERROR(INDEX('Исходник'!$1:$626,MATCH($A3,'Исходник'!$T:$T,0),MATCH(Y$1,'Исходник'!$1:$1,0)))} | Z3: =IF(IFERROR(SEARCH(" ",Y3))>0,SUM(IFERROR(VALUE(REPLACE(LEFT(Y3,SEARCH(" ",Y3)-1),SEARCH(".",LEFT(Y3,SEARCH(" ",Y3)-1),1),1,",")),LEFT(Y3,SEARCH(" ",Y3)-1)),IFERROR(VALUE(REPLACE(MID(Y3,SEARCH(" ",Y3)+1,LEN(Y3)-SEARCH(" ",Y3)),SEARCH(".",MID(Y3,SEARCH(" ",Y3)+1,LEN(Y3)-SEARCH(" ",Y3)),1),1,",")),MID(Y3,SEARCH(" ",Y3)+1,LEN(Y3)-SEARCH(" ",Y3)))),0) -> 0 | AA3: =IF(Z3>0,Z3,IFERROR(VALUE(REPLACE(Y3,SEARCH(".",Y3,1),1,",")),Y3)) | AB3: {=IFERROR(INDEX('Исходник'!$1:$626,MATCH($A3,'Исходник'!$T:$T,0),MATCH(AB$1,'Исходник'!$1:$1,0)))} | AC3: {=IFERROR(INDEX('Исходник'!$1:$626,MATCH($A3,'Исходник'!$T:$T,0),MATCH(AC$1,'Исходник'!$1:$1,0)))} | AD3: =IFERROR(VALUE(REPLACE(AC3,SEARCH(".",AC3,1),1,",")),AC3) | AE3: {=IFERROR(INDEX('Исходник'!$1:$626,MATCH($A3,'Исходник'!$T:$T,0),MATCH(AE$1,'Исходник'!$1:$1,0)))} | AF3: {=IFERROR(INDEX('Исходник'!$1:$626,MATCH($A3,'Исходник'!$T:$T,0),MATCH(AF$1,'Исходник'!$1:$1,0)))} | AG3: =IFERROR(VALUE(REPLACE(AF3,SEARCH(".",AF3,1),1,",")),AF3) | AH3: {=IFERROR(INDEX('Исходник'!$1:$626,MATCH($A3,'Исходник'!$T:$T,0),MATCH(AH$1,'Исходник'!$1:$1,0)))} | AI3: {=IFERROR(INDEX('Исходник'!$1:$626,MATCH($A3,'Исходник'!$T:$T,0),MATCH(AI$1,'Исходник'!$1:$1,0)))} | AJ3: =VALUE(LEFT(AI3,10)) -> 0
